Internal Server Error: /admin/app/author_books/
Traceback (most recent call last):
  File "/Users/hemali/lib/python3.9/site-packages/django/db/backends/utils.py", line 89, in _execute
    return self.cursor.execute(sql, params)
psycopg2.errors.UndefinedColumn: column Author_Books.Author_author_id_id does not exist
LINE 1: SELECT "Author_Books"."id", "Author_Books"."Author_author_id...
                                    ^


The above exception was the direct cause of the following exception:

Traceback (most recent call last):
  File "/Users/hemali/lib/python3.9/site-packages/django/core/handlers/exception.py", line 56, in inner
    response = get_response(request)
  File "/Users/hemali/lib/python3.9/site-packages/django/core/handlers/base.py", line 197, in _get_response
    response = wrapped_callback(request, *callback_args, **callback_kwargs)
  File "/Users/hemali/lib/python3.9/site-packages/django/contrib/admin/options.py", line 686, in wrapper
    return self.admin_site.admin_view(view)(*args, **kwargs)
  File "/Users/hemali/lib/python3.9/site-packages/django/utils/decorators.py", line 134, in _wrapped_view
    response = view_func(request, *args, **kwargs)
  File "/Users/hemali/lib/python3.9/site-packages/django/views/decorators/cache.py", line 62, in _wrapped_view_func
    response = view_func(request, *args, **kwargs)
  File "/Users/hemali/lib/python3.9/site-packages/django/contrib/admin/sites.py", line 242, in inner
    return view(request, *args, **kwargs)
  File "/Users/hemali/lib/python3.9/site-packages/django/utils/decorators.py", line 46, in _wrapper
    return bound_method(*args, **kwargs)
  File "/Users/hemali/lib/python3.9/site-packages/django/utils/decorators.py", line 134, in _wrapped_view
    response = view_func(request, *args, **kwargs)
  File "/Users/hemali/lib/python3.9/site-packages/django/contrib/admin/options.py", line 2069, in changelist_view
    "selection_note": _("0 of %(cnt)s selected") % {"cnt": len(cl.result_list)},
  File "/Users/hemali/lib/python3.9/site-packages/django/db/models/query.py", line 376, in __len__
    self._fetch_all()
  File "/Users/hemali/lib/python3.9/site-packages/django/db/models/query.py", line 1867, in _fetch_all
    self._result_cache = list(self._iterable_class(self))
  File "/Users/hemali/lib/python3.9/site-packages/django/db/models/query.py", line 87, in __iter__
    results = compiler.execute_sql(
  File "/Users/hemali/lib/python3.9/site-packages/django/db/models/sql/compiler.py", line 1398, in execute_sql
    cursor.execute(sql, params)
  File "/Users/hemali/lib/python3.9/site-packages/django/db/backends/utils.py", line 102, in execute
    return super().execute(sql, params)
  File "/Users/hemali/lib/python3.9/site-packages/django/db/backends/utils.py", line 67, in execute
    return self._execute_with_wrappers(
  File "/Users/hemali/lib/python3.9/site-packages/django/db/backends/utils.py", line 80, in _execute_with_wrappers
    return executor(sql, params, many, context)
  File "/Users/hemali/lib/python3.9/site-packages/django/db/backends/utils.py", line 89, in _execute
    return self.cursor.execute(sql, params)
  File "/Users/hemali/lib/python3.9/site-packages/django/db/utils.py", line 91, in __exit__
    raise dj_exc_value.with_traceback(traceback) from exc_value
  File "/Users/hemali/lib/python3.9/site-packages/django/db/backends/utils.py", line 89, in _execute
    return self.cursor.execute(sql, params)
django.db.utils.ProgrammingError: column Author_Books.Author_author_id_id does not exist
LINE 1: SELECT "Author_Books"."id", "Author_Books"."Author_author_id...
                                    ^

"GET /admin/app/author_books/ HTTP/1.1" 500 143877
Internal Server Error: /admin/app/author_books/
Traceback (most recent call last):
  File "/Users/hemali/lib/python3.9/site-packages/django/db/backends/utils.py", line 89, in _execute
    return self.cursor.execute(sql, params)
psycopg2.errors.UndefinedColumn: column Author_Books.Author_author_id_id does not exist
LINE 1: SELECT "Author_Books"."id", "Author_Books"."Author_author_id...
                                    ^


The above exception was the direct cause of the following exception:

Traceback (most recent call last):
  File "/Users/hemali/lib/python3.9/site-packages/django/core/handlers/exception.py", line 56, in inner
    response = get_response(request)
  File "/Users/hemali/lib/python3.9/site-packages/django/core/handlers/base.py", line 197, in _get_response
    response = wrapped_callback(request, *callback_args, **callback_kwargs)
  File "/Users/hemali/lib/python3.9/site-packages/django/contrib/admin/options.py", line 686, in wrapper
    return self.admin_site.admin_view(view)(*args, **kwargs)
  File "/Users/hemali/lib/python3.9/site-packages/django/utils/decorators.py", line 134, in _wrapped_view
    response = view_func(request, *args, **kwargs)
  File "/Users/hemali/lib/python3.9/site-packages/django/views/decorators/cache.py", line 62, in _wrapped_view_func
    response = view_func(request, *args, **kwargs)
  File "/Users/hemali/lib/python3.9/site-packages/django/contrib/admin/sites.py", line 242, in inner
    return view(request, *args, **kwargs)
  File "/Users/hemali/lib/python3.9/site-packages/django/utils/decorators.py", line 46, in _wrapper
    return bound_method(*args, **kwargs)
  File "/Users/hemali/lib/python3.9/site-packages/django/utils/decorators.py", line 134, in _wrapped_view
    response = view_func(request, *args, **kwargs)
  File "/Users/hemali/lib/python3.9/site-packages/django/contrib/admin/options.py", line 2069, in changelist_view
    "selection_note": _("0 of %(cnt)s selected") % {"cnt": len(cl.result_list)},
  File "/Users/hemali/lib/python3.9/site-packages/django/db/models/query.py", line 376, in __len__
    self._fetch_all()
  File "/Users/hemali/lib/python3.9/site-packages/django/db/models/query.py", line 1867, in _fetch_all
    self._result_cache = list(self._iterable_class(self))
  File "/Users/hemali/lib/python3.9/site-packages/django/db/models/query.py", line 87, in __iter__
    results = compiler.execute_sql(
  File "/Users/hemali/lib/python3.9/site-packages/django/db/models/sql/compiler.py", line 1398, in execute_sql
    cursor.execute(sql, params)
  File "/Users/hemali/lib/python3.9/site-packages/django/db/backends/utils.py", line 102, in execute
    return super().execute(sql, params)
  File "/Users/hemali/lib/python3.9/site-packages/django/db/backends/utils.py", line 67, in execute
    return self._execute_with_wrappers(
  File "/Users/hemali/lib/python3.9/site-packages/django/db/backends/utils.py", line 80, in _execute_with_wrappers
    return executor(sql, params, many, context)
  File "/Users/hemali/lib/python3.9/site-packages/django/db/backends/utils.py", line 89, in _execute
    return self.cursor.execute(sql, params)
  File "/Users/hemali/lib/python3.9/site-packages/django/db/utils.py", line 91, in __exit__
    raise dj_exc_value.with_traceback(traceback) from exc_value
  File "/Users/hemali/lib/python3.9/site-packages/django/db/backends/utils.py", line 89, in _execute
    return self.cursor.execute(sql, params)
django.db.utils.ProgrammingError: column Author_Books.Author_author_id_id does not exist
LINE 1: SELECT "Author_Books"."id", "Author_Books"."Author_author_id...
                                    ^

"GET /admin/app/author_books/ HTTP/1.1" 500 143890
Internal Server Error: /admin/app/publisher_user/
Traceback (most recent call last):
  File "/Users/hemali/lib/python3.9/site-packages/django/db/backends/utils.py", line 89, in _execute
    return self.cursor.execute(sql, params)
psycopg2.errors.UndefinedColumn: column PublisherUser.Publisher_publisher_id_id does not exist
LINE 1: SELECT "PublisherUser"."id", "PublisherUser"."Publisher_publ...
                                     ^


The above exception was the direct cause of the following exception:

Traceback (most recent call last):
  File "/Users/hemali/lib/python3.9/site-packages/django/core/handlers/exception.py", line 56, in inner
    response = get_response(request)
  File "/Users/hemali/lib/python3.9/site-packages/django/core/handlers/base.py", line 197, in _get_response
    response = wrapped_callback(request, *callback_args, **callback_kwargs)
  File "/Users/hemali/lib/python3.9/site-packages/django/contrib/admin/options.py", line 686, in wrapper
    return self.admin_site.admin_view(view)(*args, **kwargs)
  File "/Users/hemali/lib/python3.9/site-packages/django/utils/decorators.py", line 134, in _wrapped_view
    response = view_func(request, *args, **kwargs)
  File "/Users/hemali/lib/python3.9/site-packages/django/views/decorators/cache.py", line 62, in _wrapped_view_func
    response = view_func(request, *args, **kwargs)
  File "/Users/hemali/lib/python3.9/site-packages/django/contrib/admin/sites.py", line 242, in inner
    return view(request, *args, **kwargs)
  File "/Users/hemali/lib/python3.9/site-packages/django/utils/decorators.py", line 46, in _wrapper
    return bound_method(*args, **kwargs)
  File "/Users/hemali/lib/python3.9/site-packages/django/utils/decorators.py", line 134, in _wrapped_view
    response = view_func(request, *args, **kwargs)
  File "/Users/hemali/lib/python3.9/site-packages/django/contrib/admin/options.py", line 2069, in changelist_view
    "selection_note": _("0 of %(cnt)s selected") % {"cnt": len(cl.result_list)},
  File "/Users/hemali/lib/python3.9/site-packages/django/db/models/query.py", line 376, in __len__
    self._fetch_all()
  File "/Users/hemali/lib/python3.9/site-packages/django/db/models/query.py", line 1867, in _fetch_all
    self._result_cache = list(self._iterable_class(self))
  File "/Users/hemali/lib/python3.9/site-packages/django/db/models/query.py", line 87, in __iter__
    results = compiler.execute_sql(
  File "/Users/hemali/lib/python3.9/site-packages/django/db/models/sql/compiler.py", line 1398, in execute_sql
    cursor.execute(sql, params)
  File "/Users/hemali/lib/python3.9/site-packages/django/db/backends/utils.py", line 102, in execute
    return super().execute(sql, params)
  File "/Users/hemali/lib/python3.9/site-packages/django/db/backends/utils.py", line 67, in execute
    return self._execute_with_wrappers(
  File "/Users/hemali/lib/python3.9/site-packages/django/db/backends/utils.py", line 80, in _execute_with_wrappers
    return executor(sql, params, many, context)
  File "/Users/hemali/lib/python3.9/site-packages/django/db/backends/utils.py", line 89, in _execute
    return self.cursor.execute(sql, params)
  File "/Users/hemali/lib/python3.9/site-packages/django/db/utils.py", line 91, in __exit__
    raise dj_exc_value.with_traceback(traceback) from exc_value
  File "/Users/hemali/lib/python3.9/site-packages/django/db/backends/utils.py", line 89, in _execute
    return self.cursor.execute(sql, params)
django.db.utils.ProgrammingError: column PublisherUser.Publisher_publisher_id_id does not exist
LINE 1: SELECT "PublisherUser"."id", "PublisherUser"."Publisher_publ...
                                     ^

"GET /admin/app/publisher_user/ HTTP/1.1" 500 144097
Internal Server Error: /admin/app/author_books/
Traceback (most recent call last):
  File "/Users/hemali/lib/python3.9/site-packages/django/db/backends/utils.py", line 89, in _execute
    return self.cursor.execute(sql, params)
psycopg2.errors.UndefinedColumn: column Author_Books.Author_author_id_id does not exist
LINE 1: SELECT "Author_Books"."id", "Author_Books"."Author_author_id...
                                    ^


The above exception was the direct cause of the following exception:

Traceback (most recent call last):
  File "/Users/hemali/lib/python3.9/site-packages/django/core/handlers/exception.py", line 56, in inner
    response = get_response(request)
  File "/Users/hemali/lib/python3.9/site-packages/django/core/handlers/base.py", line 197, in _get_response
    response = wrapped_callback(request, *callback_args, **callback_kwargs)
  File "/Users/hemali/lib/python3.9/site-packages/django/contrib/admin/options.py", line 686, in wrapper
    return self.admin_site.admin_view(view)(*args, **kwargs)
  File "/Users/hemali/lib/python3.9/site-packages/django/utils/decorators.py", line 134, in _wrapped_view
    response = view_func(request, *args, **kwargs)
  File "/Users/hemali/lib/python3.9/site-packages/django/views/decorators/cache.py", line 62, in _wrapped_view_func
    response = view_func(request, *args, **kwargs)
  File "/Users/hemali/lib/python3.9/site-packages/django/contrib/admin/sites.py", line 242, in inner
    return view(request, *args, **kwargs)
  File "/Users/hemali/lib/python3.9/site-packages/django/utils/decorators.py", line 46, in _wrapper
    return bound_method(*args, **kwargs)
  File "/Users/hemali/lib/python3.9/site-packages/django/utils/decorators.py", line 134, in _wrapped_view
    response = view_func(request, *args, **kwargs)
  File "/Users/hemali/lib/python3.9/site-packages/django/contrib/admin/options.py", line 2069, in changelist_view
    "selection_note": _("0 of %(cnt)s selected") % {"cnt": len(cl.result_list)},
  File "/Users/hemali/lib/python3.9/site-packages/django/db/models/query.py", line 376, in __len__
    self._fetch_all()
  File "/Users/hemali/lib/python3.9/site-packages/django/db/models/query.py", line 1867, in _fetch_all
    self._result_cache = list(self._iterable_class(self))
  File "/Users/hemali/lib/python3.9/site-packages/django/db/models/query.py", line 87, in __iter__
    results = compiler.execute_sql(
  File "/Users/hemali/lib/python3.9/site-packages/django/db/models/sql/compiler.py", line 1398, in execute_sql
    cursor.execute(sql, params)
  File "/Users/hemali/lib/python3.9/site-packages/django/db/backends/utils.py", line 102, in execute
    return super().execute(sql, params)
  File "/Users/hemali/lib/python3.9/site-packages/django/db/backends/utils.py", line 67, in execute
    return self._execute_with_wrappers(
  File "/Users/hemali/lib/python3.9/site-packages/django/db/backends/utils.py", line 80, in _execute_with_wrappers
    return executor(sql, params, many, context)
  File "/Users/hemali/lib/python3.9/site-packages/django/db/backends/utils.py", line 89, in _execute
    return self.cursor.execute(sql, params)
  File "/Users/hemali/lib/python3.9/site-packages/django/db/utils.py", line 91, in __exit__
    raise dj_exc_value.with_traceback(traceback) from exc_value
  File "/Users/hemali/lib/python3.9/site-packages/django/db/backends/utils.py", line 89, in _execute
    return self.cursor.execute(sql, params)
django.db.utils.ProgrammingError: column Author_Books.Author_author_id_id does not exist
LINE 1: SELECT "Author_Books"."id", "Author_Books"."Author_author_id...
                                    ^

"GET /admin/app/author_books/ HTTP/1.1" 500 143881
Internal Server Error: /admin/app/publisher_user/
Traceback (most recent call last):
  File "/Users/hemali/lib/python3.9/site-packages/django/db/backends/utils.py", line 89, in _execute
    return self.cursor.execute(sql, params)
psycopg2.errors.UndefinedColumn: column PublisherUser.Publisher_publisher_id_id does not exist
LINE 1: SELECT "PublisherUser"."id", "PublisherUser"."Publisher_publ...
                                     ^


The above exception was the direct cause of the following exception:

Traceback (most recent call last):
  File "/Users/hemali/lib/python3.9/site-packages/django/core/handlers/exception.py", line 56, in inner
    response = get_response(request)
  File "/Users/hemali/lib/python3.9/site-packages/django/core/handlers/base.py", line 197, in _get_response
    response = wrapped_callback(request, *callback_args, **callback_kwargs)
  File "/Users/hemali/lib/python3.9/site-packages/django/contrib/admin/options.py", line 686, in wrapper
    return self.admin_site.admin_view(view)(*args, **kwargs)
  File "/Users/hemali/lib/python3.9/site-packages/django/utils/decorators.py", line 134, in _wrapped_view
    response = view_func(request, *args, **kwargs)
  File "/Users/hemali/lib/python3.9/site-packages/django/views/decorators/cache.py", line 62, in _wrapped_view_func
    response = view_func(request, *args, **kwargs)
  File "/Users/hemali/lib/python3.9/site-packages/django/contrib/admin/sites.py", line 242, in inner
    return view(request, *args, **kwargs)
  File "/Users/hemali/lib/python3.9/site-packages/django/utils/decorators.py", line 46, in _wrapper
    return bound_method(*args, **kwargs)
  File "/Users/hemali/lib/python3.9/site-packages/django/utils/decorators.py", line 134, in _wrapped_view
    response = view_func(request, *args, **kwargs)
  File "/Users/hemali/lib/python3.9/site-packages/django/contrib/admin/options.py", line 2069, in changelist_view
    "selection_note": _("0 of %(cnt)s selected") % {"cnt": len(cl.result_list)},
  File "/Users/hemali/lib/python3.9/site-packages/django/db/models/query.py", line 376, in __len__
    self._fetch_all()
  File "/Users/hemali/lib/python3.9/site-packages/django/db/models/query.py", line 1867, in _fetch_all
    self._result_cache = list(self._iterable_class(self))
  File "/Users/hemali/lib/python3.9/site-packages/django/db/models/query.py", line 87, in __iter__
    results = compiler.execute_sql(
  File "/Users/hemali/lib/python3.9/site-packages/django/db/models/sql/compiler.py", line 1398, in execute_sql
    cursor.execute(sql, params)
  File "/Users/hemali/lib/python3.9/site-packages/django/db/backends/utils.py", line 102, in execute
    return super().execute(sql, params)
  File "/Users/hemali/lib/python3.9/site-packages/django/db/backends/utils.py", line 67, in execute
    return self._execute_with_wrappers(
  File "/Users/hemali/lib/python3.9/site-packages/django/db/backends/utils.py", line 80, in _execute_with_wrappers
    return executor(sql, params, many, context)
  File "/Users/hemali/lib/python3.9/site-packages/django/db/backends/utils.py", line 89, in _execute
    return self.cursor.execute(sql, params)
  File "/Users/hemali/lib/python3.9/site-packages/django/db/utils.py", line 91, in __exit__
    raise dj_exc_value.with_traceback(traceback) from exc_value
  File "/Users/hemali/lib/python3.9/site-packages/django/db/backends/utils.py", line 89, in _execute
    return self.cursor.execute(sql, params)
django.db.utils.ProgrammingError: column PublisherUser.Publisher_publisher_id_id does not exist
LINE 1: SELECT "PublisherUser"."id", "PublisherUser"."Publisher_publ...
                                     ^

"GET /admin/app/publisher_user/ HTTP/1.1" 500 144104
Internal Server Error: /admin/app/publisher_user/
Traceback (most recent call last):
  File "/Users/hemali/lib/python3.9/site-packages/django/db/backends/utils.py", line 89, in _execute
    return self.cursor.execute(sql, params)
psycopg2.errors.UndefinedTable: relation "Publisher_User" does not exist
LINE 1: SELECT COUNT(*) AS "__count" FROM "Publisher_User"
                                          ^


The above exception was the direct cause of the following exception:

Traceback (most recent call last):
  File "/Users/hemali/lib/python3.9/site-packages/django/core/handlers/exception.py", line 56, in inner
    response = get_response(request)
  File "/Users/hemali/lib/python3.9/site-packages/django/core/handlers/base.py", line 197, in _get_response
    response = wrapped_callback(request, *callback_args, **callback_kwargs)
  File "/Users/hemali/lib/python3.9/site-packages/django/contrib/admin/options.py", line 686, in wrapper
    return self.admin_site.admin_view(view)(*args, **kwargs)
  File "/Users/hemali/lib/python3.9/site-packages/django/utils/decorators.py", line 134, in _wrapped_view
    response = view_func(request, *args, **kwargs)
  File "/Users/hemali/lib/python3.9/site-packages/django/views/decorators/cache.py", line 62, in _wrapped_view_func
    response = view_func(request, *args, **kwargs)
  File "/Users/hemali/lib/python3.9/site-packages/django/contrib/admin/sites.py", line 242, in inner
    return view(request, *args, **kwargs)
  File "/Users/hemali/lib/python3.9/site-packages/django/utils/decorators.py", line 46, in _wrapper
    return bound_method(*args, **kwargs)
  File "/Users/hemali/lib/python3.9/site-packages/django/utils/decorators.py", line 134, in _wrapped_view
    response = view_func(request, *args, **kwargs)
  File "/Users/hemali/lib/python3.9/site-packages/django/contrib/admin/options.py", line 1932, in changelist_view
    cl = self.get_changelist_instance(request)
  File "/Users/hemali/lib/python3.9/site-packages/django/contrib/admin/options.py", line 834, in get_changelist_instance
    return ChangeList(
  File "/Users/hemali/lib/python3.9/site-packages/django/contrib/admin/views/main.py", line 123, in __init__
    self.get_results(request)
  File "/Users/hemali/lib/python3.9/site-packages/django/contrib/admin/views/main.py", line 279, in get_results
    result_count = paginator.count
  File "/Users/hemali/lib/python3.9/site-packages/django/utils/functional.py", line 57, in __get__
    res = instance.__dict__[self.name] = self.func(instance)
  File "/Users/hemali/lib/python3.9/site-packages/django/core/paginator.py", line 96, in count
    return c()
  File "/Users/hemali/lib/python3.9/site-packages/django/db/models/query.py", line 621, in count
    return self.query.get_count(using=self.db)
  File "/Users/hemali/lib/python3.9/site-packages/django/db/models/sql/query.py", line 559, in get_count
    return obj.get_aggregation(using, ["__count"])["__count"]
  File "/Users/hemali/lib/python3.9/site-packages/django/db/models/sql/query.py", line 544, in get_aggregation
    result = compiler.execute_sql(SINGLE)
  File "/Users/hemali/lib/python3.9/site-packages/django/db/models/sql/compiler.py", line 1398, in execute_sql
    cursor.execute(sql, params)
  File "/Users/hemali/lib/python3.9/site-packages/django/db/backends/utils.py", line 102, in execute
    return super().execute(sql, params)
  File "/Users/hemali/lib/python3.9/site-packages/django/db/backends/utils.py", line 67, in execute
    return self._execute_with_wrappers(
  File "/Users/hemali/lib/python3.9/site-packages/django/db/backends/utils.py", line 80, in _execute_with_wrappers
    return executor(sql, params, many, context)
  File "/Users/hemali/lib/python3.9/site-packages/django/db/backends/utils.py", line 89, in _execute
    return self.cursor.execute(sql, params)
  File "/Users/hemali/lib/python3.9/site-packages/django/db/utils.py", line 91, in __exit__
    raise dj_exc_value.with_traceback(traceback) from exc_value
  File "/Users/hemali/lib/python3.9/site-packages/django/db/backends/utils.py", line 89, in _execute
    return self.cursor.execute(sql, params)
django.db.utils.ProgrammingError: relation "Publisher_User" does not exist
LINE 1: SELECT COUNT(*) AS "__count" FROM "Publisher_User"
                                          ^

"GET /admin/app/publisher_user/ HTTP/1.1" 500 164929
Internal Server Error: /admin/app/books_publisher/
Traceback (most recent call last):
  File "/Users/hemali/lib/python3.9/site-packages/django/db/backends/utils.py", line 89, in _execute
    return self.cursor.execute(sql, params)
psycopg2.errors.UndefinedColumn: column Books_Publisher.book_id_id does not exist
LINE 1: SELECT "Books_Publisher"."id", "Books_Publisher"."book_id_id...
                                       ^


The above exception was the direct cause of the following exception:

Traceback (most recent call last):
  File "/Users/hemali/lib/python3.9/site-packages/django/core/handlers/exception.py", line 56, in inner
    response = get_response(request)
  File "/Users/hemali/lib/python3.9/site-packages/django/core/handlers/base.py", line 197, in _get_response
    response = wrapped_callback(request, *callback_args, **callback_kwargs)
  File "/Users/hemali/lib/python3.9/site-packages/django/contrib/admin/options.py", line 686, in wrapper
    return self.admin_site.admin_view(view)(*args, **kwargs)
  File "/Users/hemali/lib/python3.9/site-packages/django/utils/decorators.py", line 134, in _wrapped_view
    response = view_func(request, *args, **kwargs)
  File "/Users/hemali/lib/python3.9/site-packages/django/views/decorators/cache.py", line 62, in _wrapped_view_func
    response = view_func(request, *args, **kwargs)
  File "/Users/hemali/lib/python3.9/site-packages/django/contrib/admin/sites.py", line 242, in inner
    return view(request, *args, **kwargs)
  File "/Users/hemali/lib/python3.9/site-packages/django/utils/decorators.py", line 46, in _wrapper
    return bound_method(*args, **kwargs)
  File "/Users/hemali/lib/python3.9/site-packages/django/utils/decorators.py", line 134, in _wrapped_view
    response = view_func(request, *args, **kwargs)
  File "/Users/hemali/lib/python3.9/site-packages/django/contrib/admin/options.py", line 2069, in changelist_view
    "selection_note": _("0 of %(cnt)s selected") % {"cnt": len(cl.result_list)},
  File "/Users/hemali/lib/python3.9/site-packages/django/db/models/query.py", line 376, in __len__
    self._fetch_all()
  File "/Users/hemali/lib/python3.9/site-packages/django/db/models/query.py", line 1867, in _fetch_all
    self._result_cache = list(self._iterable_class(self))
  File "/Users/hemali/lib/python3.9/site-packages/django/db/models/query.py", line 87, in __iter__
    results = compiler.execute_sql(
  File "/Users/hemali/lib/python3.9/site-packages/django/db/models/sql/compiler.py", line 1398, in execute_sql
    cursor.execute(sql, params)
  File "/Users/hemali/lib/python3.9/site-packages/django/db/backends/utils.py", line 102, in execute
    return super().execute(sql, params)
  File "/Users/hemali/lib/python3.9/site-packages/django/db/backends/utils.py", line 67, in execute
    return self._execute_with_wrappers(
  File "/Users/hemali/lib/python3.9/site-packages/django/db/backends/utils.py", line 80, in _execute_with_wrappers
    return executor(sql, params, many, context)
  File "/Users/hemali/lib/python3.9/site-packages/django/db/backends/utils.py", line 89, in _execute
    return self.cursor.execute(sql, params)
  File "/Users/hemali/lib/python3.9/site-packages/django/db/utils.py", line 91, in __exit__
    raise dj_exc_value.with_traceback(traceback) from exc_value
  File "/Users/hemali/lib/python3.9/site-packages/django/db/backends/utils.py", line 89, in _execute
    return self.cursor.execute(sql, params)
django.db.utils.ProgrammingError: column Books_Publisher.book_id_id does not exist
LINE 1: SELECT "Books_Publisher"."id", "Books_Publisher"."book_id_id...
                                       ^

"GET /admin/app/books_publisher/ HTTP/1.1" 500 143974
Internal Server Error: /admin/app/books_publisher/
Traceback (most recent call last):
  File "/Users/hemali/lib/python3.9/site-packages/django/db/backends/utils.py", line 89, in _execute
    return self.cursor.execute(sql, params)
psycopg2.errors.UndefinedColumn: column Books_Publisher.book_id_id_id does not exist
LINE 1: SELECT "Books_Publisher"."id", "Books_Publisher"."book_id_id...
                                       ^


The above exception was the direct cause of the following exception:

Traceback (most recent call last):
  File "/Users/hemali/lib/python3.9/site-packages/django/core/handlers/exception.py", line 56, in inner
    response = get_response(request)
  File "/Users/hemali/lib/python3.9/site-packages/django/core/handlers/base.py", line 197, in _get_response
    response = wrapped_callback(request, *callback_args, **callback_kwargs)
  File "/Users/hemali/lib/python3.9/site-packages/django/contrib/admin/options.py", line 686, in wrapper
    return self.admin_site.admin_view(view)(*args, **kwargs)
  File "/Users/hemali/lib/python3.9/site-packages/django/utils/decorators.py", line 134, in _wrapped_view
    response = view_func(request, *args, **kwargs)
  File "/Users/hemali/lib/python3.9/site-packages/django/views/decorators/cache.py", line 62, in _wrapped_view_func
    response = view_func(request, *args, **kwargs)
  File "/Users/hemali/lib/python3.9/site-packages/django/contrib/admin/sites.py", line 242, in inner
    return view(request, *args, **kwargs)
  File "/Users/hemali/lib/python3.9/site-packages/django/utils/decorators.py", line 46, in _wrapper
    return bound_method(*args, **kwargs)
  File "/Users/hemali/lib/python3.9/site-packages/django/utils/decorators.py", line 134, in _wrapped_view
    response = view_func(request, *args, **kwargs)
  File "/Users/hemali/lib/python3.9/site-packages/django/contrib/admin/options.py", line 2069, in changelist_view
    "selection_note": _("0 of %(cnt)s selected") % {"cnt": len(cl.result_list)},
  File "/Users/hemali/lib/python3.9/site-packages/django/db/models/query.py", line 376, in __len__
    self._fetch_all()
  File "/Users/hemali/lib/python3.9/site-packages/django/db/models/query.py", line 1867, in _fetch_all
    self._result_cache = list(self._iterable_class(self))
  File "/Users/hemali/lib/python3.9/site-packages/django/db/models/query.py", line 87, in __iter__
    results = compiler.execute_sql(
  File "/Users/hemali/lib/python3.9/site-packages/django/db/models/sql/compiler.py", line 1398, in execute_sql
    cursor.execute(sql, params)
  File "/Users/hemali/lib/python3.9/site-packages/django/db/backends/utils.py", line 102, in execute
    return super().execute(sql, params)
  File "/Users/hemali/lib/python3.9/site-packages/django/db/backends/utils.py", line 67, in execute
    return self._execute_with_wrappers(
  File "/Users/hemali/lib/python3.9/site-packages/django/db/backends/utils.py", line 80, in _execute_with_wrappers
    return executor(sql, params, many, context)
  File "/Users/hemali/lib/python3.9/site-packages/django/db/backends/utils.py", line 89, in _execute
    return self.cursor.execute(sql, params)
  File "/Users/hemali/lib/python3.9/site-packages/django/db/utils.py", line 91, in __exit__
    raise dj_exc_value.with_traceback(traceback) from exc_value
  File "/Users/hemali/lib/python3.9/site-packages/django/db/backends/utils.py", line 89, in _execute
    return self.cursor.execute(sql, params)
django.db.utils.ProgrammingError: column Books_Publisher.book_id_id_id does not exist
LINE 1: SELECT "Books_Publisher"."id", "Books_Publisher"."book_id_id...
                                       ^

"GET /admin/app/books_publisher/ HTTP/1.1" 500 144165
Internal Server Error: /admin/app/publisher_user/
Traceback (most recent call last):
  File "/Users/hemali/lib/python3.9/site-packages/django/db/backends/utils.py", line 89, in _execute
    return self.cursor.execute(sql, params)
psycopg2.errors.UndefinedTable: relation "Publisher_User" does not exist
LINE 1: SELECT COUNT(*) AS "__count" FROM "Publisher_User"
                                          ^


The above exception was the direct cause of the following exception:

Traceback (most recent call last):
  File "/Users/hemali/lib/python3.9/site-packages/django/core/handlers/exception.py", line 56, in inner
    response = get_response(request)
  File "/Users/hemali/lib/python3.9/site-packages/django/core/handlers/base.py", line 197, in _get_response
    response = wrapped_callback(request, *callback_args, **callback_kwargs)
  File "/Users/hemali/lib/python3.9/site-packages/django/contrib/admin/options.py", line 686, in wrapper
    return self.admin_site.admin_view(view)(*args, **kwargs)
  File "/Users/hemali/lib/python3.9/site-packages/django/utils/decorators.py", line 134, in _wrapped_view
    response = view_func(request, *args, **kwargs)
  File "/Users/hemali/lib/python3.9/site-packages/django/views/decorators/cache.py", line 62, in _wrapped_view_func
    response = view_func(request, *args, **kwargs)
  File "/Users/hemali/lib/python3.9/site-packages/django/contrib/admin/sites.py", line 242, in inner
    return view(request, *args, **kwargs)
  File "/Users/hemali/lib/python3.9/site-packages/django/utils/decorators.py", line 46, in _wrapper
    return bound_method(*args, **kwargs)
  File "/Users/hemali/lib/python3.9/site-packages/django/utils/decorators.py", line 134, in _wrapped_view
    response = view_func(request, *args, **kwargs)
  File "/Users/hemali/lib/python3.9/site-packages/django/contrib/admin/options.py", line 1932, in changelist_view
    cl = self.get_changelist_instance(request)
  File "/Users/hemali/lib/python3.9/site-packages/django/contrib/admin/options.py", line 834, in get_changelist_instance
    return ChangeList(
  File "/Users/hemali/lib/python3.9/site-packages/django/contrib/admin/views/main.py", line 123, in __init__
    self.get_results(request)
  File "/Users/hemali/lib/python3.9/site-packages/django/contrib/admin/views/main.py", line 279, in get_results
    result_count = paginator.count
  File "/Users/hemali/lib/python3.9/site-packages/django/utils/functional.py", line 57, in __get__
    res = instance.__dict__[self.name] = self.func(instance)
  File "/Users/hemali/lib/python3.9/site-packages/django/core/paginator.py", line 96, in count
    return c()
  File "/Users/hemali/lib/python3.9/site-packages/django/db/models/query.py", line 621, in count
    return self.query.get_count(using=self.db)
  File "/Users/hemali/lib/python3.9/site-packages/django/db/models/sql/query.py", line 559, in get_count
    return obj.get_aggregation(using, ["__count"])["__count"]
  File "/Users/hemali/lib/python3.9/site-packages/django/db/models/sql/query.py", line 544, in get_aggregation
    result = compiler.execute_sql(SINGLE)
  File "/Users/hemali/lib/python3.9/site-packages/django/db/models/sql/compiler.py", line 1398, in execute_sql
    cursor.execute(sql, params)
  File "/Users/hemali/lib/python3.9/site-packages/django/db/backends/utils.py", line 102, in execute
    return super().execute(sql, params)
  File "/Users/hemali/lib/python3.9/site-packages/django/db/backends/utils.py", line 67, in execute
    return self._execute_with_wrappers(
  File "/Users/hemali/lib/python3.9/site-packages/django/db/backends/utils.py", line 80, in _execute_with_wrappers
    return executor(sql, params, many, context)
  File "/Users/hemali/lib/python3.9/site-packages/django/db/backends/utils.py", line 89, in _execute
    return self.cursor.execute(sql, params)
  File "/Users/hemali/lib/python3.9/site-packages/django/db/utils.py", line 91, in __exit__
    raise dj_exc_value.with_traceback(traceback) from exc_value
  File "/Users/hemali/lib/python3.9/site-packages/django/db/backends/utils.py", line 89, in _execute
    return self.cursor.execute(sql, params)
django.db.utils.ProgrammingError: relation "Publisher_User" does not exist
LINE 1: SELECT COUNT(*) AS "__count" FROM "Publisher_User"
                                          ^

"GET /admin/app/publisher_user/ HTTP/1.1" 500 164775
Internal Server Error: /admin/app/publisher_user/
Traceback (most recent call last):
  File "/Users/hemali/lib/python3.9/site-packages/django/db/backends/utils.py", line 89, in _execute
    return self.cursor.execute(sql, params)
psycopg2.errors.UndefinedTable: relation "Publisher_User" does not exist
LINE 1: SELECT COUNT(*) AS "__count" FROM "Publisher_User"
                                          ^


The above exception was the direct cause of the following exception:

Traceback (most recent call last):
  File "/Users/hemali/lib/python3.9/site-packages/django/core/handlers/exception.py", line 56, in inner
    response = get_response(request)
  File "/Users/hemali/lib/python3.9/site-packages/django/core/handlers/base.py", line 197, in _get_response
    response = wrapped_callback(request, *callback_args, **callback_kwargs)
  File "/Users/hemali/lib/python3.9/site-packages/django/contrib/admin/options.py", line 686, in wrapper
    return self.admin_site.admin_view(view)(*args, **kwargs)
  File "/Users/hemali/lib/python3.9/site-packages/django/utils/decorators.py", line 134, in _wrapped_view
    response = view_func(request, *args, **kwargs)
  File "/Users/hemali/lib/python3.9/site-packages/django/views/decorators/cache.py", line 62, in _wrapped_view_func
    response = view_func(request, *args, **kwargs)
  File "/Users/hemali/lib/python3.9/site-packages/django/contrib/admin/sites.py", line 242, in inner
    return view(request, *args, **kwargs)
  File "/Users/hemali/lib/python3.9/site-packages/django/utils/decorators.py", line 46, in _wrapper
    return bound_method(*args, **kwargs)
  File "/Users/hemali/lib/python3.9/site-packages/django/utils/decorators.py", line 134, in _wrapped_view
    response = view_func(request, *args, **kwargs)
  File "/Users/hemali/lib/python3.9/site-packages/django/contrib/admin/options.py", line 1932, in changelist_view
    cl = self.get_changelist_instance(request)
  File "/Users/hemali/lib/python3.9/site-packages/django/contrib/admin/options.py", line 834, in get_changelist_instance
    return ChangeList(
  File "/Users/hemali/lib/python3.9/site-packages/django/contrib/admin/views/main.py", line 123, in __init__
    self.get_results(request)
  File "/Users/hemali/lib/python3.9/site-packages/django/contrib/admin/views/main.py", line 279, in get_results
    result_count = paginator.count
  File "/Users/hemali/lib/python3.9/site-packages/django/utils/functional.py", line 57, in __get__
    res = instance.__dict__[self.name] = self.func(instance)
  File "/Users/hemali/lib/python3.9/site-packages/django/core/paginator.py", line 96, in count
    return c()
  File "/Users/hemali/lib/python3.9/site-packages/django/db/models/query.py", line 621, in count
    return self.query.get_count(using=self.db)
  File "/Users/hemali/lib/python3.9/site-packages/django/db/models/sql/query.py", line 559, in get_count
    return obj.get_aggregation(using, ["__count"])["__count"]
  File "/Users/hemali/lib/python3.9/site-packages/django/db/models/sql/query.py", line 544, in get_aggregation
    result = compiler.execute_sql(SINGLE)
  File "/Users/hemali/lib/python3.9/site-packages/django/db/models/sql/compiler.py", line 1398, in execute_sql
    cursor.execute(sql, params)
  File "/Users/hemali/lib/python3.9/site-packages/django/db/backends/utils.py", line 102, in execute
    return super().execute(sql, params)
  File "/Users/hemali/lib/python3.9/site-packages/django/db/backends/utils.py", line 67, in execute
    return self._execute_with_wrappers(
  File "/Users/hemali/lib/python3.9/site-packages/django/db/backends/utils.py", line 80, in _execute_with_wrappers
    return executor(sql, params, many, context)
  File "/Users/hemali/lib/python3.9/site-packages/django/db/backends/utils.py", line 89, in _execute
    return self.cursor.execute(sql, params)
  File "/Users/hemali/lib/python3.9/site-packages/django/db/utils.py", line 91, in __exit__
    raise dj_exc_value.with_traceback(traceback) from exc_value
  File "/Users/hemali/lib/python3.9/site-packages/django/db/backends/utils.py", line 89, in _execute
    return self.cursor.execute(sql, params)
django.db.utils.ProgrammingError: relation "Publisher_User" does not exist
LINE 1: SELECT COUNT(*) AS "__count" FROM "Publisher_User"
                                          ^

"GET /admin/app/publisher_user/ HTTP/1.1" 500 164912
Internal Server Error: /admin/app/publisher_user/
Traceback (most recent call last):
  File "/Users/hemali/lib/python3.9/site-packages/django/db/backends/utils.py", line 89, in _execute
    return self.cursor.execute(sql, params)
psycopg2.errors.UndefinedTable: relation "Publisher_User" does not exist
LINE 1: SELECT COUNT(*) AS "__count" FROM "Publisher_User"
                                          ^


The above exception was the direct cause of the following exception:

Traceback (most recent call last):
  File "/Users/hemali/lib/python3.9/site-packages/django/core/handlers/exception.py", line 56, in inner
    response = get_response(request)
  File "/Users/hemali/lib/python3.9/site-packages/django/core/handlers/base.py", line 197, in _get_response
    response = wrapped_callback(request, *callback_args, **callback_kwargs)
  File "/Users/hemali/lib/python3.9/site-packages/django/contrib/admin/options.py", line 686, in wrapper
    return self.admin_site.admin_view(view)(*args, **kwargs)
  File "/Users/hemali/lib/python3.9/site-packages/django/utils/decorators.py", line 134, in _wrapped_view
    response = view_func(request, *args, **kwargs)
  File "/Users/hemali/lib/python3.9/site-packages/django/views/decorators/cache.py", line 62, in _wrapped_view_func
    response = view_func(request, *args, **kwargs)
  File "/Users/hemali/lib/python3.9/site-packages/django/contrib/admin/sites.py", line 242, in inner
    return view(request, *args, **kwargs)
  File "/Users/hemali/lib/python3.9/site-packages/django/utils/decorators.py", line 46, in _wrapper
    return bound_method(*args, **kwargs)
  File "/Users/hemali/lib/python3.9/site-packages/django/utils/decorators.py", line 134, in _wrapped_view
    response = view_func(request, *args, **kwargs)
  File "/Users/hemali/lib/python3.9/site-packages/django/contrib/admin/options.py", line 1932, in changelist_view
    cl = self.get_changelist_instance(request)
  File "/Users/hemali/lib/python3.9/site-packages/django/contrib/admin/options.py", line 834, in get_changelist_instance
    return ChangeList(
  File "/Users/hemali/lib/python3.9/site-packages/django/contrib/admin/views/main.py", line 123, in __init__
    self.get_results(request)
  File "/Users/hemali/lib/python3.9/site-packages/django/contrib/admin/views/main.py", line 279, in get_results
    result_count = paginator.count
  File "/Users/hemali/lib/python3.9/site-packages/django/utils/functional.py", line 57, in __get__
    res = instance.__dict__[self.name] = self.func(instance)
  File "/Users/hemali/lib/python3.9/site-packages/django/core/paginator.py", line 96, in count
    return c()
  File "/Users/hemali/lib/python3.9/site-packages/django/db/models/query.py", line 621, in count
    return self.query.get_count(using=self.db)
  File "/Users/hemali/lib/python3.9/site-packages/django/db/models/sql/query.py", line 559, in get_count
    return obj.get_aggregation(using, ["__count"])["__count"]
  File "/Users/hemali/lib/python3.9/site-packages/django/db/models/sql/query.py", line 544, in get_aggregation
    result = compiler.execute_sql(SINGLE)
  File "/Users/hemali/lib/python3.9/site-packages/django/db/models/sql/compiler.py", line 1398, in execute_sql
    cursor.execute(sql, params)
  File "/Users/hemali/lib/python3.9/site-packages/django/db/backends/utils.py", line 102, in execute
    return super().execute(sql, params)
  File "/Users/hemali/lib/python3.9/site-packages/django/db/backends/utils.py", line 67, in execute
    return self._execute_with_wrappers(
  File "/Users/hemali/lib/python3.9/site-packages/django/db/backends/utils.py", line 80, in _execute_with_wrappers
    return executor(sql, params, many, context)
  File "/Users/hemali/lib/python3.9/site-packages/django/db/backends/utils.py", line 89, in _execute
    return self.cursor.execute(sql, params)
  File "/Users/hemali/lib/python3.9/site-packages/django/db/utils.py", line 91, in __exit__
    raise dj_exc_value.with_traceback(traceback) from exc_value
  File "/Users/hemali/lib/python3.9/site-packages/django/db/backends/utils.py", line 89, in _execute
    return self.cursor.execute(sql, params)
django.db.utils.ProgrammingError: relation "Publisher_User" does not exist
LINE 1: SELECT COUNT(*) AS "__count" FROM "Publisher_User"
                                          ^

"GET /admin/app/publisher_user/ HTTP/1.1" 500 164785
Internal Server Error: /admin/app/user_author/
Traceback (most recent call last):
  File "/Users/hemali/lib/python3.9/site-packages/django/db/backends/utils.py", line 89, in _execute
    return self.cursor.execute(sql, params)
psycopg2.errors.UndefinedColumn: column User_Author.User_user_id_id does not exist
LINE 1: SELECT "User_Author"."id", "User_Author"."User_user_id_id", ...
                                   ^


The above exception was the direct cause of the following exception:

Traceback (most recent call last):
  File "/Users/hemali/lib/python3.9/site-packages/django/core/handlers/exception.py", line 56, in inner
    response = get_response(request)
  File "/Users/hemali/lib/python3.9/site-packages/django/core/handlers/base.py", line 197, in _get_response
    response = wrapped_callback(request, *callback_args, **callback_kwargs)
  File "/Users/hemali/lib/python3.9/site-packages/django/contrib/admin/options.py", line 686, in wrapper
    return self.admin_site.admin_view(view)(*args, **kwargs)
  File "/Users/hemali/lib/python3.9/site-packages/django/utils/decorators.py", line 134, in _wrapped_view
    response = view_func(request, *args, **kwargs)
  File "/Users/hemali/lib/python3.9/site-packages/django/views/decorators/cache.py", line 62, in _wrapped_view_func
    response = view_func(request, *args, **kwargs)
  File "/Users/hemali/lib/python3.9/site-packages/django/contrib/admin/sites.py", line 242, in inner
    return view(request, *args, **kwargs)
  File "/Users/hemali/lib/python3.9/site-packages/django/utils/decorators.py", line 46, in _wrapper
    return bound_method(*args, **kwargs)
  File "/Users/hemali/lib/python3.9/site-packages/django/utils/decorators.py", line 134, in _wrapped_view
    response = view_func(request, *args, **kwargs)
  File "/Users/hemali/lib/python3.9/site-packages/django/contrib/admin/options.py", line 2069, in changelist_view
    "selection_note": _("0 of %(cnt)s selected") % {"cnt": len(cl.result_list)},
  File "/Users/hemali/lib/python3.9/site-packages/django/db/models/query.py", line 376, in __len__
    self._fetch_all()
  File "/Users/hemali/lib/python3.9/site-packages/django/db/models/query.py", line 1867, in _fetch_all
    self._result_cache = list(self._iterable_class(self))
  File "/Users/hemali/lib/python3.9/site-packages/django/db/models/query.py", line 87, in __iter__
    results = compiler.execute_sql(
  File "/Users/hemali/lib/python3.9/site-packages/django/db/models/sql/compiler.py", line 1398, in execute_sql
    cursor.execute(sql, params)
  File "/Users/hemali/lib/python3.9/site-packages/django/db/backends/utils.py", line 102, in execute
    return super().execute(sql, params)
  File "/Users/hemali/lib/python3.9/site-packages/django/db/backends/utils.py", line 67, in execute
    return self._execute_with_wrappers(
  File "/Users/hemali/lib/python3.9/site-packages/django/db/backends/utils.py", line 80, in _execute_with_wrappers
    return executor(sql, params, many, context)
  File "/Users/hemali/lib/python3.9/site-packages/django/db/backends/utils.py", line 89, in _execute
    return self.cursor.execute(sql, params)
  File "/Users/hemali/lib/python3.9/site-packages/django/db/utils.py", line 91, in __exit__
    raise dj_exc_value.with_traceback(traceback) from exc_value
  File "/Users/hemali/lib/python3.9/site-packages/django/db/backends/utils.py", line 89, in _execute
    return self.cursor.execute(sql, params)
django.db.utils.ProgrammingError: column User_Author.User_user_id_id does not exist
LINE 1: SELECT "User_Author"."id", "User_Author"."User_user_id_id", ...
                                   ^

"GET /admin/app/user_author/ HTTP/1.1" 500 143812
Internal Server Error: /admin/app/author/
Traceback (most recent call last):
  File "/Users/hemali/lib/python3.9/site-packages/django/db/backends/utils.py", line 89, in _execute
    return self.cursor.execute(sql, params)
psycopg2.errors.UndefinedTable: relation "Author" does not exist
LINE 1: SELECT COUNT(*) AS "__count" FROM "Author"
                                          ^


The above exception was the direct cause of the following exception:

Traceback (most recent call last):
  File "/Users/hemali/lib/python3.9/site-packages/django/core/handlers/exception.py", line 56, in inner
    response = get_response(request)
  File "/Users/hemali/lib/python3.9/site-packages/django/core/handlers/base.py", line 197, in _get_response
    response = wrapped_callback(request, *callback_args, **callback_kwargs)
  File "/Users/hemali/lib/python3.9/site-packages/django/contrib/admin/options.py", line 686, in wrapper
    return self.admin_site.admin_view(view)(*args, **kwargs)
  File "/Users/hemali/lib/python3.9/site-packages/django/utils/decorators.py", line 134, in _wrapped_view
    response = view_func(request, *args, **kwargs)
  File "/Users/hemali/lib/python3.9/site-packages/django/views/decorators/cache.py", line 62, in _wrapped_view_func
    response = view_func(request, *args, **kwargs)
  File "/Users/hemali/lib/python3.9/site-packages/django/contrib/admin/sites.py", line 242, in inner
    return view(request, *args, **kwargs)
  File "/Users/hemali/lib/python3.9/site-packages/django/utils/decorators.py", line 46, in _wrapper
    return bound_method(*args, **kwargs)
  File "/Users/hemali/lib/python3.9/site-packages/django/utils/decorators.py", line 134, in _wrapped_view
    response = view_func(request, *args, **kwargs)
  File "/Users/hemali/lib/python3.9/site-packages/django/contrib/admin/options.py", line 1932, in changelist_view
    cl = self.get_changelist_instance(request)
  File "/Users/hemali/lib/python3.9/site-packages/django/contrib/admin/options.py", line 834, in get_changelist_instance
    return ChangeList(
  File "/Users/hemali/lib/python3.9/site-packages/django/contrib/admin/views/main.py", line 123, in __init__
    self.get_results(request)
  File "/Users/hemali/lib/python3.9/site-packages/django/contrib/admin/views/main.py", line 279, in get_results
    result_count = paginator.count
  File "/Users/hemali/lib/python3.9/site-packages/django/utils/functional.py", line 57, in __get__
    res = instance.__dict__[self.name] = self.func(instance)
  File "/Users/hemali/lib/python3.9/site-packages/django/core/paginator.py", line 96, in count
    return c()
  File "/Users/hemali/lib/python3.9/site-packages/django/db/models/query.py", line 621, in count
    return self.query.get_count(using=self.db)
  File "/Users/hemali/lib/python3.9/site-packages/django/db/models/sql/query.py", line 559, in get_count
    return obj.get_aggregation(using, ["__count"])["__count"]
  File "/Users/hemali/lib/python3.9/site-packages/django/db/models/sql/query.py", line 544, in get_aggregation
    result = compiler.execute_sql(SINGLE)
  File "/Users/hemali/lib/python3.9/site-packages/django/db/models/sql/compiler.py", line 1398, in execute_sql
    cursor.execute(sql, params)
  File "/Users/hemali/lib/python3.9/site-packages/django/db/backends/utils.py", line 102, in execute
    return super().execute(sql, params)
  File "/Users/hemali/lib/python3.9/site-packages/django/db/backends/utils.py", line 67, in execute
    return self._execute_with_wrappers(
  File "/Users/hemali/lib/python3.9/site-packages/django/db/backends/utils.py", line 80, in _execute_with_wrappers
    return executor(sql, params, many, context)
  File "/Users/hemali/lib/python3.9/site-packages/django/db/backends/utils.py", line 89, in _execute
    return self.cursor.execute(sql, params)
  File "/Users/hemali/lib/python3.9/site-packages/django/db/utils.py", line 91, in __exit__
    raise dj_exc_value.with_traceback(traceback) from exc_value
  File "/Users/hemali/lib/python3.9/site-packages/django/db/backends/utils.py", line 89, in _execute
    return self.cursor.execute(sql, params)
django.db.utils.ProgrammingError: relation "Author" does not exist
LINE 1: SELECT COUNT(*) AS "__count" FROM "Author"
                                          ^

"GET /admin/app/author/ HTTP/1.1" 500 164641
Internal Server Error: /admin/app/books/
Traceback (most recent call last):
  File "/Users/hemali/lib/python3.9/site-packages/django/db/backends/utils.py", line 89, in _execute
    return self.cursor.execute(sql, params)
psycopg2.errors.UndefinedTable: relation "Books" does not exist
LINE 1: SELECT COUNT(*) AS "__count" FROM "Books"
                                          ^


The above exception was the direct cause of the following exception:

Traceback (most recent call last):
  File "/Users/hemali/lib/python3.9/site-packages/django/core/handlers/exception.py", line 56, in inner
    response = get_response(request)
  File "/Users/hemali/lib/python3.9/site-packages/django/core/handlers/base.py", line 197, in _get_response
    response = wrapped_callback(request, *callback_args, **callback_kwargs)
  File "/Users/hemali/lib/python3.9/site-packages/django/contrib/admin/options.py", line 686, in wrapper
    return self.admin_site.admin_view(view)(*args, **kwargs)
  File "/Users/hemali/lib/python3.9/site-packages/django/utils/decorators.py", line 134, in _wrapped_view
    response = view_func(request, *args, **kwargs)
  File "/Users/hemali/lib/python3.9/site-packages/django/views/decorators/cache.py", line 62, in _wrapped_view_func
    response = view_func(request, *args, **kwargs)
  File "/Users/hemali/lib/python3.9/site-packages/django/contrib/admin/sites.py", line 242, in inner
    return view(request, *args, **kwargs)
  File "/Users/hemali/lib/python3.9/site-packages/django/utils/decorators.py", line 46, in _wrapper
    return bound_method(*args, **kwargs)
  File "/Users/hemali/lib/python3.9/site-packages/django/utils/decorators.py", line 134, in _wrapped_view
    response = view_func(request, *args, **kwargs)
  File "/Users/hemali/lib/python3.9/site-packages/django/contrib/admin/options.py", line 1932, in changelist_view
    cl = self.get_changelist_instance(request)
  File "/Users/hemali/lib/python3.9/site-packages/django/contrib/admin/options.py", line 834, in get_changelist_instance
    return ChangeList(
  File "/Users/hemali/lib/python3.9/site-packages/django/contrib/admin/views/main.py", line 123, in __init__
    self.get_results(request)
  File "/Users/hemali/lib/python3.9/site-packages/django/contrib/admin/views/main.py", line 279, in get_results
    result_count = paginator.count
  File "/Users/hemali/lib/python3.9/site-packages/django/utils/functional.py", line 57, in __get__
    res = instance.__dict__[self.name] = self.func(instance)
  File "/Users/hemali/lib/python3.9/site-packages/django/core/paginator.py", line 96, in count
    return c()
  File "/Users/hemali/lib/python3.9/site-packages/django/db/models/query.py", line 621, in count
    return self.query.get_count(using=self.db)
  File "/Users/hemali/lib/python3.9/site-packages/django/db/models/sql/query.py", line 559, in get_count
    return obj.get_aggregation(using, ["__count"])["__count"]
  File "/Users/hemali/lib/python3.9/site-packages/django/db/models/sql/query.py", line 544, in get_aggregation
    result = compiler.execute_sql(SINGLE)
  File "/Users/hemali/lib/python3.9/site-packages/django/db/models/sql/compiler.py", line 1398, in execute_sql
    cursor.execute(sql, params)
  File "/Users/hemali/lib/python3.9/site-packages/django/db/backends/utils.py", line 102, in execute
    return super().execute(sql, params)
  File "/Users/hemali/lib/python3.9/site-packages/django/db/backends/utils.py", line 67, in execute
    return self._execute_with_wrappers(
  File "/Users/hemali/lib/python3.9/site-packages/django/db/backends/utils.py", line 80, in _execute_with_wrappers
    return executor(sql, params, many, context)
  File "/Users/hemali/lib/python3.9/site-packages/django/db/backends/utils.py", line 89, in _execute
    return self.cursor.execute(sql, params)
  File "/Users/hemali/lib/python3.9/site-packages/django/db/utils.py", line 91, in __exit__
    raise dj_exc_value.with_traceback(traceback) from exc_value
  File "/Users/hemali/lib/python3.9/site-packages/django/db/backends/utils.py", line 89, in _execute
    return self.cursor.execute(sql, params)
django.db.utils.ProgrammingError: relation "Books" does not exist
LINE 1: SELECT COUNT(*) AS "__count" FROM "Books"
                                          ^

"GET /admin/app/books/ HTTP/1.1" 500 164263
Internal Server Error: /admin/app/offer/
Traceback (most recent call last):
  File "/Users/hemali/lib/python3.9/site-packages/django/db/backends/utils.py", line 89, in _execute
    return self.cursor.execute(sql, params)
psycopg2.errors.UndefinedTable: relation "Offer" does not exist
LINE 1: SELECT COUNT(*) AS "__count" FROM "Offer"
                                          ^


The above exception was the direct cause of the following exception:

Traceback (most recent call last):
  File "/Users/hemali/lib/python3.9/site-packages/django/core/handlers/exception.py", line 56, in inner
    response = get_response(request)
  File "/Users/hemali/lib/python3.9/site-packages/django/core/handlers/base.py", line 197, in _get_response
    response = wrapped_callback(request, *callback_args, **callback_kwargs)
  File "/Users/hemali/lib/python3.9/site-packages/django/contrib/admin/options.py", line 686, in wrapper
    return self.admin_site.admin_view(view)(*args, **kwargs)
  File "/Users/hemali/lib/python3.9/site-packages/django/utils/decorators.py", line 134, in _wrapped_view
    response = view_func(request, *args, **kwargs)
  File "/Users/hemali/lib/python3.9/site-packages/django/views/decorators/cache.py", line 62, in _wrapped_view_func
    response = view_func(request, *args, **kwargs)
  File "/Users/hemali/lib/python3.9/site-packages/django/contrib/admin/sites.py", line 242, in inner
    return view(request, *args, **kwargs)
  File "/Users/hemali/lib/python3.9/site-packages/django/utils/decorators.py", line 46, in _wrapper
    return bound_method(*args, **kwargs)
  File "/Users/hemali/lib/python3.9/site-packages/django/utils/decorators.py", line 134, in _wrapped_view
    response = view_func(request, *args, **kwargs)
  File "/Users/hemali/lib/python3.9/site-packages/django/contrib/admin/options.py", line 1932, in changelist_view
    cl = self.get_changelist_instance(request)
  File "/Users/hemali/lib/python3.9/site-packages/django/contrib/admin/options.py", line 834, in get_changelist_instance
    return ChangeList(
  File "/Users/hemali/lib/python3.9/site-packages/django/contrib/admin/views/main.py", line 123, in __init__
    self.get_results(request)
  File "/Users/hemali/lib/python3.9/site-packages/django/contrib/admin/views/main.py", line 279, in get_results
    result_count = paginator.count
  File "/Users/hemali/lib/python3.9/site-packages/django/utils/functional.py", line 57, in __get__
    res = instance.__dict__[self.name] = self.func(instance)
  File "/Users/hemali/lib/python3.9/site-packages/django/core/paginator.py", line 96, in count
    return c()
  File "/Users/hemali/lib/python3.9/site-packages/django/db/models/query.py", line 621, in count
    return self.query.get_count(using=self.db)
  File "/Users/hemali/lib/python3.9/site-packages/django/db/models/sql/query.py", line 559, in get_count
    return obj.get_aggregation(using, ["__count"])["__count"]
  File "/Users/hemali/lib/python3.9/site-packages/django/db/models/sql/query.py", line 544, in get_aggregation
    result = compiler.execute_sql(SINGLE)
  File "/Users/hemali/lib/python3.9/site-packages/django/db/models/sql/compiler.py", line 1398, in execute_sql
    cursor.execute(sql, params)
  File "/Users/hemali/lib/python3.9/site-packages/django/db/backends/utils.py", line 102, in execute
    return super().execute(sql, params)
  File "/Users/hemali/lib/python3.9/site-packages/django/db/backends/utils.py", line 67, in execute
    return self._execute_with_wrappers(
  File "/Users/hemali/lib/python3.9/site-packages/django/db/backends/utils.py", line 80, in _execute_with_wrappers
    return executor(sql, params, many, context)
  File "/Users/hemali/lib/python3.9/site-packages/django/db/backends/utils.py", line 89, in _execute
    return self.cursor.execute(sql, params)
  File "/Users/hemali/lib/python3.9/site-packages/django/db/utils.py", line 91, in __exit__
    raise dj_exc_value.with_traceback(traceback) from exc_value
  File "/Users/hemali/lib/python3.9/site-packages/django/db/backends/utils.py", line 89, in _execute
    return self.cursor.execute(sql, params)
django.db.utils.ProgrammingError: relation "Offer" does not exist
LINE 1: SELECT COUNT(*) AS "__count" FROM "Offer"
                                          ^

"GET /admin/app/offer/ HTTP/1.1" 500 164303
Internal Server Error: /admin/app/category/11/change/
Traceback (most recent call last):
  File "/Users/hemali/lib/python3.9/site-packages/django/db/backends/utils.py", line 89, in _execute
    return self.cursor.execute(sql, params)
psycopg2.errors.UndefinedTable: relation "Category" does not exist
LINE 1: ...y"."category_id", "Category"."category_name" FROM "Category"...
                                                             ^


The above exception was the direct cause of the following exception:

Traceback (most recent call last):
  File "/Users/hemali/lib/python3.9/site-packages/django/core/handlers/exception.py", line 56, in inner
    response = get_response(request)
  File "/Users/hemali/lib/python3.9/site-packages/django/core/handlers/base.py", line 197, in _get_response
    response = wrapped_callback(request, *callback_args, **callback_kwargs)
  File "/Users/hemali/lib/python3.9/site-packages/django/contrib/admin/options.py", line 686, in wrapper
    return self.admin_site.admin_view(view)(*args, **kwargs)
  File "/Users/hemali/lib/python3.9/site-packages/django/utils/decorators.py", line 134, in _wrapped_view
    response = view_func(request, *args, **kwargs)
  File "/Users/hemali/lib/python3.9/site-packages/django/views/decorators/cache.py", line 62, in _wrapped_view_func
    response = view_func(request, *args, **kwargs)
  File "/Users/hemali/lib/python3.9/site-packages/django/contrib/admin/sites.py", line 242, in inner
    return view(request, *args, **kwargs)
  File "/Users/hemali/lib/python3.9/site-packages/django/contrib/admin/options.py", line 1894, in change_view
    return self.changeform_view(request, object_id, form_url, extra_context)
  File "/Users/hemali/lib/python3.9/site-packages/django/utils/decorators.py", line 46, in _wrapper
    return bound_method(*args, **kwargs)
  File "/Users/hemali/lib/python3.9/site-packages/django/utils/decorators.py", line 134, in _wrapped_view
    response = view_func(request, *args, **kwargs)
  File "/Users/hemali/lib/python3.9/site-packages/django/contrib/admin/options.py", line 1751, in changeform_view
    return self._changeform_view(request, object_id, form_url, extra_context)
  File "/Users/hemali/lib/python3.9/site-packages/django/contrib/admin/options.py", line 1774, in _changeform_view
    obj = self.get_object(request, unquote(object_id), to_field)
  File "/Users/hemali/lib/python3.9/site-packages/django/contrib/admin/options.py", line 864, in get_object
    return queryset.get(**{field.name: object_id})
  File "/Users/hemali/lib/python3.9/site-packages/django/db/models/query.py", line 646, in get
    num = len(clone)
  File "/Users/hemali/lib/python3.9/site-packages/django/db/models/query.py", line 376, in __len__
    self._fetch_all()
  File "/Users/hemali/lib/python3.9/site-packages/django/db/models/query.py", line 1867, in _fetch_all
    self._result_cache = list(self._iterable_class(self))
  File "/Users/hemali/lib/python3.9/site-packages/django/db/models/query.py", line 87, in __iter__
    results = compiler.execute_sql(
  File "/Users/hemali/lib/python3.9/site-packages/django/db/models/sql/compiler.py", line 1398, in execute_sql
    cursor.execute(sql, params)
  File "/Users/hemali/lib/python3.9/site-packages/django/db/backends/utils.py", line 102, in execute
    return super().execute(sql, params)
  File "/Users/hemali/lib/python3.9/site-packages/django/db/backends/utils.py", line 67, in execute
    return self._execute_with_wrappers(
  File "/Users/hemali/lib/python3.9/site-packages/django/db/backends/utils.py", line 80, in _execute_with_wrappers
    return executor(sql, params, many, context)
  File "/Users/hemali/lib/python3.9/site-packages/django/db/backends/utils.py", line 89, in _execute
    return self.cursor.execute(sql, params)
  File "/Users/hemali/lib/python3.9/site-packages/django/db/utils.py", line 91, in __exit__
    raise dj_exc_value.with_traceback(traceback) from exc_value
  File "/Users/hemali/lib/python3.9/site-packages/django/db/backends/utils.py", line 89, in _execute
    return self.cursor.execute(sql, params)
django.db.utils.ProgrammingError: relation "Category" does not exist
LINE 1: ...y"."category_id", "Category"."category_name" FROM "Category"...
                                                             ^

"GET /admin/app/category/11/change/ HTTP/1.1" 500 161486
Internal Server Error: /admin/app/author_books/
Traceback (most recent call last):
  File "/Users/hemali/lib/python3.9/site-packages/django/db/backends/utils.py", line 89, in _execute
    return self.cursor.execute(sql, params)
psycopg2.errors.UndefinedTable: relation "Author_Books" does not exist
LINE 1: SELECT COUNT(*) AS "__count" FROM "Author_Books"
                                          ^


The above exception was the direct cause of the following exception:

Traceback (most recent call last):
  File "/Users/hemali/lib/python3.9/site-packages/django/core/handlers/exception.py", line 56, in inner
    response = get_response(request)
  File "/Users/hemali/lib/python3.9/site-packages/django/core/handlers/base.py", line 197, in _get_response
    response = wrapped_callback(request, *callback_args, **callback_kwargs)
  File "/Users/hemali/lib/python3.9/site-packages/django/contrib/admin/options.py", line 686, in wrapper
    return self.admin_site.admin_view(view)(*args, **kwargs)
  File "/Users/hemali/lib/python3.9/site-packages/django/utils/decorators.py", line 134, in _wrapped_view
    response = view_func(request, *args, **kwargs)
  File "/Users/hemali/lib/python3.9/site-packages/django/views/decorators/cache.py", line 62, in _wrapped_view_func
    response = view_func(request, *args, **kwargs)
  File "/Users/hemali/lib/python3.9/site-packages/django/contrib/admin/sites.py", line 242, in inner
    return view(request, *args, **kwargs)
  File "/Users/hemali/lib/python3.9/site-packages/django/utils/decorators.py", line 46, in _wrapper
    return bound_method(*args, **kwargs)
  File "/Users/hemali/lib/python3.9/site-packages/django/utils/decorators.py", line 134, in _wrapped_view
    response = view_func(request, *args, **kwargs)
  File "/Users/hemali/lib/python3.9/site-packages/django/contrib/admin/options.py", line 1932, in changelist_view
    cl = self.get_changelist_instance(request)
  File "/Users/hemali/lib/python3.9/site-packages/django/contrib/admin/options.py", line 834, in get_changelist_instance
    return ChangeList(
  File "/Users/hemali/lib/python3.9/site-packages/django/contrib/admin/views/main.py", line 123, in __init__
    self.get_results(request)
  File "/Users/hemali/lib/python3.9/site-packages/django/contrib/admin/views/main.py", line 279, in get_results
    result_count = paginator.count
  File "/Users/hemali/lib/python3.9/site-packages/django/utils/functional.py", line 57, in __get__
    res = instance.__dict__[self.name] = self.func(instance)
  File "/Users/hemali/lib/python3.9/site-packages/django/core/paginator.py", line 96, in count
    return c()
  File "/Users/hemali/lib/python3.9/site-packages/django/db/models/query.py", line 621, in count
    return self.query.get_count(using=self.db)
  File "/Users/hemali/lib/python3.9/site-packages/django/db/models/sql/query.py", line 559, in get_count
    return obj.get_aggregation(using, ["__count"])["__count"]
  File "/Users/hemali/lib/python3.9/site-packages/django/db/models/sql/query.py", line 544, in get_aggregation
    result = compiler.execute_sql(SINGLE)
  File "/Users/hemali/lib/python3.9/site-packages/django/db/models/sql/compiler.py", line 1398, in execute_sql
    cursor.execute(sql, params)
  File "/Users/hemali/lib/python3.9/site-packages/django/db/backends/utils.py", line 102, in execute
    return super().execute(sql, params)
  File "/Users/hemali/lib/python3.9/site-packages/django/db/backends/utils.py", line 67, in execute
    return self._execute_with_wrappers(
  File "/Users/hemali/lib/python3.9/site-packages/django/db/backends/utils.py", line 80, in _execute_with_wrappers
    return executor(sql, params, many, context)
  File "/Users/hemali/lib/python3.9/site-packages/django/db/backends/utils.py", line 89, in _execute
    return self.cursor.execute(sql, params)
  File "/Users/hemali/lib/python3.9/site-packages/django/db/utils.py", line 91, in __exit__
    raise dj_exc_value.with_traceback(traceback) from exc_value
  File "/Users/hemali/lib/python3.9/site-packages/django/db/backends/utils.py", line 89, in _execute
    return self.cursor.execute(sql, params)
django.db.utils.ProgrammingError: relation "Author_Books" does not exist
LINE 1: SELECT COUNT(*) AS "__count" FROM "Author_Books"
                                          ^

"GET /admin/app/author_books/ HTTP/1.1" 500 164669
Internal Server Error: /admin/app/books_publisher/
Traceback (most recent call last):
  File "/Users/hemali/lib/python3.9/site-packages/django/db/backends/utils.py", line 89, in _execute
    return self.cursor.execute(sql, params)
psycopg2.errors.UndefinedTable: relation "Books_Publisher" does not exist
LINE 1: SELECT COUNT(*) AS "__count" FROM "Books_Publisher"
                                          ^


The above exception was the direct cause of the following exception:

Traceback (most recent call last):
  File "/Users/hemali/lib/python3.9/site-packages/django/core/handlers/exception.py", line 56, in inner
    response = get_response(request)
  File "/Users/hemali/lib/python3.9/site-packages/django/core/handlers/base.py", line 197, in _get_response
    response = wrapped_callback(request, *callback_args, **callback_kwargs)
  File "/Users/hemali/lib/python3.9/site-packages/django/contrib/admin/options.py", line 686, in wrapper
    return self.admin_site.admin_view(view)(*args, **kwargs)
  File "/Users/hemali/lib/python3.9/site-packages/django/utils/decorators.py", line 134, in _wrapped_view
    response = view_func(request, *args, **kwargs)
  File "/Users/hemali/lib/python3.9/site-packages/django/views/decorators/cache.py", line 62, in _wrapped_view_func
    response = view_func(request, *args, **kwargs)
  File "/Users/hemali/lib/python3.9/site-packages/django/contrib/admin/sites.py", line 242, in inner
    return view(request, *args, **kwargs)
  File "/Users/hemali/lib/python3.9/site-packages/django/utils/decorators.py", line 46, in _wrapper
    return bound_method(*args, **kwargs)
  File "/Users/hemali/lib/python3.9/site-packages/django/utils/decorators.py", line 134, in _wrapped_view
    response = view_func(request, *args, **kwargs)
  File "/Users/hemali/lib/python3.9/site-packages/django/contrib/admin/options.py", line 1932, in changelist_view
    cl = self.get_changelist_instance(request)
  File "/Users/hemali/lib/python3.9/site-packages/django/contrib/admin/options.py", line 834, in get_changelist_instance
    return ChangeList(
  File "/Users/hemali/lib/python3.9/site-packages/django/contrib/admin/views/main.py", line 123, in __init__
    self.get_results(request)
  File "/Users/hemali/lib/python3.9/site-packages/django/contrib/admin/views/main.py", line 279, in get_results
    result_count = paginator.count
  File "/Users/hemali/lib/python3.9/site-packages/django/utils/functional.py", line 57, in __get__
    res = instance.__dict__[self.name] = self.func(instance)
  File "/Users/hemali/lib/python3.9/site-packages/django/core/paginator.py", line 96, in count
    return c()
  File "/Users/hemali/lib/python3.9/site-packages/django/db/models/query.py", line 621, in count
    return self.query.get_count(using=self.db)
  File "/Users/hemali/lib/python3.9/site-packages/django/db/models/sql/query.py", line 559, in get_count
    return obj.get_aggregation(using, ["__count"])["__count"]
  File "/Users/hemali/lib/python3.9/site-packages/django/db/models/sql/query.py", line 544, in get_aggregation
    result = compiler.execute_sql(SINGLE)
  File "/Users/hemali/lib/python3.9/site-packages/django/db/models/sql/compiler.py", line 1398, in execute_sql
    cursor.execute(sql, params)
  File "/Users/hemali/lib/python3.9/site-packages/django/db/backends/utils.py", line 102, in execute
    return super().execute(sql, params)
  File "/Users/hemali/lib/python3.9/site-packages/django/db/backends/utils.py", line 67, in execute
    return self._execute_with_wrappers(
  File "/Users/hemali/lib/python3.9/site-packages/django/db/backends/utils.py", line 80, in _execute_with_wrappers
    return executor(sql, params, many, context)
  File "/Users/hemali/lib/python3.9/site-packages/django/db/backends/utils.py", line 89, in _execute
    return self.cursor.execute(sql, params)
  File "/Users/hemali/lib/python3.9/site-packages/django/db/utils.py", line 91, in __exit__
    raise dj_exc_value.with_traceback(traceback) from exc_value
  File "/Users/hemali/lib/python3.9/site-packages/django/db/backends/utils.py", line 89, in _execute
    return self.cursor.execute(sql, params)
django.db.utils.ProgrammingError: relation "Books_Publisher" does not exist
LINE 1: SELECT COUNT(*) AS "__count" FROM "Books_Publisher"
                                          ^

"GET /admin/app/books_publisher/ HTTP/1.1" 500 164813
Internal Server Error: /admin/app/category/
Traceback (most recent call last):
  File "/Users/hemali/lib/python3.9/site-packages/django/db/backends/utils.py", line 89, in _execute
    return self.cursor.execute(sql, params)
psycopg2.errors.UndefinedTable: relation "Category" does not exist
LINE 1: SELECT COUNT(*) AS "__count" FROM "Category"
                                          ^


The above exception was the direct cause of the following exception:

Traceback (most recent call last):
  File "/Users/hemali/lib/python3.9/site-packages/django/core/handlers/exception.py", line 56, in inner
    response = get_response(request)
  File "/Users/hemali/lib/python3.9/site-packages/django/core/handlers/base.py", line 197, in _get_response
    response = wrapped_callback(request, *callback_args, **callback_kwargs)
  File "/Users/hemali/lib/python3.9/site-packages/django/contrib/admin/options.py", line 686, in wrapper
    return self.admin_site.admin_view(view)(*args, **kwargs)
  File "/Users/hemali/lib/python3.9/site-packages/django/utils/decorators.py", line 134, in _wrapped_view
    response = view_func(request, *args, **kwargs)
  File "/Users/hemali/lib/python3.9/site-packages/django/views/decorators/cache.py", line 62, in _wrapped_view_func
    response = view_func(request, *args, **kwargs)
  File "/Users/hemali/lib/python3.9/site-packages/django/contrib/admin/sites.py", line 242, in inner
    return view(request, *args, **kwargs)
  File "/Users/hemali/lib/python3.9/site-packages/django/utils/decorators.py", line 46, in _wrapper
    return bound_method(*args, **kwargs)
  File "/Users/hemali/lib/python3.9/site-packages/django/utils/decorators.py", line 134, in _wrapped_view
    response = view_func(request, *args, **kwargs)
  File "/Users/hemali/lib/python3.9/site-packages/django/contrib/admin/options.py", line 1932, in changelist_view
    cl = self.get_changelist_instance(request)
  File "/Users/hemali/lib/python3.9/site-packages/django/contrib/admin/options.py", line 834, in get_changelist_instance
    return ChangeList(
  File "/Users/hemali/lib/python3.9/site-packages/django/contrib/admin/views/main.py", line 123, in __init__
    self.get_results(request)
  File "/Users/hemali/lib/python3.9/site-packages/django/contrib/admin/views/main.py", line 279, in get_results
    result_count = paginator.count
  File "/Users/hemali/lib/python3.9/site-packages/django/utils/functional.py", line 57, in __get__
    res = instance.__dict__[self.name] = self.func(instance)
  File "/Users/hemali/lib/python3.9/site-packages/django/core/paginator.py", line 96, in count
    return c()
  File "/Users/hemali/lib/python3.9/site-packages/django/db/models/query.py", line 621, in count
    return self.query.get_count(using=self.db)
  File "/Users/hemali/lib/python3.9/site-packages/django/db/models/sql/query.py", line 559, in get_count
    return obj.get_aggregation(using, ["__count"])["__count"]
  File "/Users/hemali/lib/python3.9/site-packages/django/db/models/sql/query.py", line 544, in get_aggregation
    result = compiler.execute_sql(SINGLE)
  File "/Users/hemali/lib/python3.9/site-packages/django/db/models/sql/compiler.py", line 1398, in execute_sql
    cursor.execute(sql, params)
  File "/Users/hemali/lib/python3.9/site-packages/django/db/backends/utils.py", line 102, in execute
    return super().execute(sql, params)
  File "/Users/hemali/lib/python3.9/site-packages/django/db/backends/utils.py", line 67, in execute
    return self._execute_with_wrappers(
  File "/Users/hemali/lib/python3.9/site-packages/django/db/backends/utils.py", line 80, in _execute_with_wrappers
    return executor(sql, params, many, context)
  File "/Users/hemali/lib/python3.9/site-packages/django/db/backends/utils.py", line 89, in _execute
    return self.cursor.execute(sql, params)
  File "/Users/hemali/lib/python3.9/site-packages/django/db/utils.py", line 91, in __exit__
    raise dj_exc_value.with_traceback(traceback) from exc_value
  File "/Users/hemali/lib/python3.9/site-packages/django/db/backends/utils.py", line 89, in _execute
    return self.cursor.execute(sql, params)
django.db.utils.ProgrammingError: relation "Category" does not exist
LINE 1: SELECT COUNT(*) AS "__count" FROM "Category"
                                          ^

"GET /admin/app/category/ HTTP/1.1" 500 164457
Internal Server Error: /admin/app/publisher/
Traceback (most recent call last):
  File "/Users/hemali/lib/python3.9/site-packages/django/db/backends/utils.py", line 89, in _execute
    return self.cursor.execute(sql, params)
psycopg2.errors.UndefinedTable: relation "Publisher" does not exist
LINE 1: SELECT COUNT(*) AS "__count" FROM "Publisher"
                                          ^


The above exception was the direct cause of the following exception:

Traceback (most recent call last):
  File "/Users/hemali/lib/python3.9/site-packages/django/core/handlers/exception.py", line 56, in inner
    response = get_response(request)
  File "/Users/hemali/lib/python3.9/site-packages/django/core/handlers/base.py", line 197, in _get_response
    response = wrapped_callback(request, *callback_args, **callback_kwargs)
  File "/Users/hemali/lib/python3.9/site-packages/django/contrib/admin/options.py", line 686, in wrapper
    return self.admin_site.admin_view(view)(*args, **kwargs)
  File "/Users/hemali/lib/python3.9/site-packages/django/utils/decorators.py", line 134, in _wrapped_view
    response = view_func(request, *args, **kwargs)
  File "/Users/hemali/lib/python3.9/site-packages/django/views/decorators/cache.py", line 62, in _wrapped_view_func
    response = view_func(request, *args, **kwargs)
  File "/Users/hemali/lib/python3.9/site-packages/django/contrib/admin/sites.py", line 242, in inner
    return view(request, *args, **kwargs)
  File "/Users/hemali/lib/python3.9/site-packages/django/utils/decorators.py", line 46, in _wrapper
    return bound_method(*args, **kwargs)
  File "/Users/hemali/lib/python3.9/site-packages/django/utils/decorators.py", line 134, in _wrapped_view
    response = view_func(request, *args, **kwargs)
  File "/Users/hemali/lib/python3.9/site-packages/django/contrib/admin/options.py", line 1932, in changelist_view
    cl = self.get_changelist_instance(request)
  File "/Users/hemali/lib/python3.9/site-packages/django/contrib/admin/options.py", line 834, in get_changelist_instance
    return ChangeList(
  File "/Users/hemali/lib/python3.9/site-packages/django/contrib/admin/views/main.py", line 123, in __init__
    self.get_results(request)
  File "/Users/hemali/lib/python3.9/site-packages/django/contrib/admin/views/main.py", line 279, in get_results
    result_count = paginator.count
  File "/Users/hemali/lib/python3.9/site-packages/django/utils/functional.py", line 57, in __get__
    res = instance.__dict__[self.name] = self.func(instance)
  File "/Users/hemali/lib/python3.9/site-packages/django/core/paginator.py", line 96, in count
    return c()
  File "/Users/hemali/lib/python3.9/site-packages/django/db/models/query.py", line 621, in count
    return self.query.get_count(using=self.db)
  File "/Users/hemali/lib/python3.9/site-packages/django/db/models/sql/query.py", line 559, in get_count
    return obj.get_aggregation(using, ["__count"])["__count"]
  File "/Users/hemali/lib/python3.9/site-packages/django/db/models/sql/query.py", line 544, in get_aggregation
    result = compiler.execute_sql(SINGLE)
  File "/Users/hemali/lib/python3.9/site-packages/django/db/models/sql/compiler.py", line 1398, in execute_sql
    cursor.execute(sql, params)
  File "/Users/hemali/lib/python3.9/site-packages/django/db/backends/utils.py", line 102, in execute
    return super().execute(sql, params)
  File "/Users/hemali/lib/python3.9/site-packages/django/db/backends/utils.py", line 67, in execute
    return self._execute_with_wrappers(
  File "/Users/hemali/lib/python3.9/site-packages/django/db/backends/utils.py", line 80, in _execute_with_wrappers
    return executor(sql, params, many, context)
  File "/Users/hemali/lib/python3.9/site-packages/django/db/backends/utils.py", line 89, in _execute
    return self.cursor.execute(sql, params)
  File "/Users/hemali/lib/python3.9/site-packages/django/db/utils.py", line 91, in __exit__
    raise dj_exc_value.with_traceback(traceback) from exc_value
  File "/Users/hemali/lib/python3.9/site-packages/django/db/backends/utils.py", line 89, in _execute
    return self.cursor.execute(sql, params)
django.db.utils.ProgrammingError: relation "Publisher" does not exist
LINE 1: SELECT COUNT(*) AS "__count" FROM "Publisher"
                                          ^

"GET /admin/app/publisher/ HTTP/1.1" 500 164505
Internal Server Error: /admin/app/review/
Traceback (most recent call last):
  File "/Users/hemali/lib/python3.9/site-packages/django/db/backends/utils.py", line 89, in _execute
    return self.cursor.execute(sql, params)
psycopg2.errors.UndefinedTable: relation "Review" does not exist
LINE 1: SELECT COUNT(*) AS "__count" FROM "Review"
                                          ^


The above exception was the direct cause of the following exception:

Traceback (most recent call last):
  File "/Users/hemali/lib/python3.9/site-packages/django/core/handlers/exception.py", line 56, in inner
    response = get_response(request)
  File "/Users/hemali/lib/python3.9/site-packages/django/core/handlers/base.py", line 197, in _get_response
    response = wrapped_callback(request, *callback_args, **callback_kwargs)
  File "/Users/hemali/lib/python3.9/site-packages/django/contrib/admin/options.py", line 686, in wrapper
    return self.admin_site.admin_view(view)(*args, **kwargs)
  File "/Users/hemali/lib/python3.9/site-packages/django/utils/decorators.py", line 134, in _wrapped_view
    response = view_func(request, *args, **kwargs)
  File "/Users/hemali/lib/python3.9/site-packages/django/views/decorators/cache.py", line 62, in _wrapped_view_func
    response = view_func(request, *args, **kwargs)
  File "/Users/hemali/lib/python3.9/site-packages/django/contrib/admin/sites.py", line 242, in inner
    return view(request, *args, **kwargs)
  File "/Users/hemali/lib/python3.9/site-packages/django/utils/decorators.py", line 46, in _wrapper
    return bound_method(*args, **kwargs)
  File "/Users/hemali/lib/python3.9/site-packages/django/utils/decorators.py", line 134, in _wrapped_view
    response = view_func(request, *args, **kwargs)
  File "/Users/hemali/lib/python3.9/site-packages/django/contrib/admin/options.py", line 1932, in changelist_view
    cl = self.get_changelist_instance(request)
  File "/Users/hemali/lib/python3.9/site-packages/django/contrib/admin/options.py", line 834, in get_changelist_instance
    return ChangeList(
  File "/Users/hemali/lib/python3.9/site-packages/django/contrib/admin/views/main.py", line 123, in __init__
    self.get_results(request)
  File "/Users/hemali/lib/python3.9/site-packages/django/contrib/admin/views/main.py", line 279, in get_results
    result_count = paginator.count
  File "/Users/hemali/lib/python3.9/site-packages/django/utils/functional.py", line 57, in __get__
    res = instance.__dict__[self.name] = self.func(instance)
  File "/Users/hemali/lib/python3.9/site-packages/django/core/paginator.py", line 96, in count
    return c()
  File "/Users/hemali/lib/python3.9/site-packages/django/db/models/query.py", line 621, in count
    return self.query.get_count(using=self.db)
  File "/Users/hemali/lib/python3.9/site-packages/django/db/models/sql/query.py", line 559, in get_count
    return obj.get_aggregation(using, ["__count"])["__count"]
  File "/Users/hemali/lib/python3.9/site-packages/django/db/models/sql/query.py", line 544, in get_aggregation
    result = compiler.execute_sql(SINGLE)
  File "/Users/hemali/lib/python3.9/site-packages/django/db/models/sql/compiler.py", line 1398, in execute_sql
    cursor.execute(sql, params)
  File "/Users/hemali/lib/python3.9/site-packages/django/db/backends/utils.py", line 102, in execute
    return super().execute(sql, params)
  File "/Users/hemali/lib/python3.9/site-packages/django/db/backends/utils.py", line 67, in execute
    return self._execute_with_wrappers(
  File "/Users/hemali/lib/python3.9/site-packages/django/db/backends/utils.py", line 80, in _execute_with_wrappers
    return executor(sql, params, many, context)
  File "/Users/hemali/lib/python3.9/site-packages/django/db/backends/utils.py", line 89, in _execute
    return self.cursor.execute(sql, params)
  File "/Users/hemali/lib/python3.9/site-packages/django/db/utils.py", line 91, in __exit__
    raise dj_exc_value.with_traceback(traceback) from exc_value
  File "/Users/hemali/lib/python3.9/site-packages/django/db/backends/utils.py", line 89, in _execute
    return self.cursor.execute(sql, params)
django.db.utils.ProgrammingError: relation "Review" does not exist
LINE 1: SELECT COUNT(*) AS "__count" FROM "Review"
                                          ^

"GET /admin/app/review/ HTTP/1.1" 500 164361
Internal Server Error: /admin/app/user/
Traceback (most recent call last):
  File "/Users/hemali/lib/python3.9/site-packages/django/db/backends/utils.py", line 89, in _execute
    return self.cursor.execute(sql, params)
psycopg2.errors.UndefinedTable: relation "User" does not exist
LINE 1: SELECT COUNT(*) AS "__count" FROM "User"
                                          ^


The above exception was the direct cause of the following exception:

Traceback (most recent call last):
  File "/Users/hemali/lib/python3.9/site-packages/django/core/handlers/exception.py", line 56, in inner
    response = get_response(request)
  File "/Users/hemali/lib/python3.9/site-packages/django/core/handlers/base.py", line 197, in _get_response
    response = wrapped_callback(request, *callback_args, **callback_kwargs)
  File "/Users/hemali/lib/python3.9/site-packages/django/contrib/admin/options.py", line 686, in wrapper
    return self.admin_site.admin_view(view)(*args, **kwargs)
  File "/Users/hemali/lib/python3.9/site-packages/django/utils/decorators.py", line 134, in _wrapped_view
    response = view_func(request, *args, **kwargs)
  File "/Users/hemali/lib/python3.9/site-packages/django/views/decorators/cache.py", line 62, in _wrapped_view_func
    response = view_func(request, *args, **kwargs)
  File "/Users/hemali/lib/python3.9/site-packages/django/contrib/admin/sites.py", line 242, in inner
    return view(request, *args, **kwargs)
  File "/Users/hemali/lib/python3.9/site-packages/django/utils/decorators.py", line 46, in _wrapper
    return bound_method(*args, **kwargs)
  File "/Users/hemali/lib/python3.9/site-packages/django/utils/decorators.py", line 134, in _wrapped_view
    response = view_func(request, *args, **kwargs)
  File "/Users/hemali/lib/python3.9/site-packages/django/contrib/admin/options.py", line 1932, in changelist_view
    cl = self.get_changelist_instance(request)
  File "/Users/hemali/lib/python3.9/site-packages/django/contrib/admin/options.py", line 834, in get_changelist_instance
    return ChangeList(
  File "/Users/hemali/lib/python3.9/site-packages/django/contrib/admin/views/main.py", line 123, in __init__
    self.get_results(request)
  File "/Users/hemali/lib/python3.9/site-packages/django/contrib/admin/views/main.py", line 279, in get_results
    result_count = paginator.count
  File "/Users/hemali/lib/python3.9/site-packages/django/utils/functional.py", line 57, in __get__
    res = instance.__dict__[self.name] = self.func(instance)
  File "/Users/hemali/lib/python3.9/site-packages/django/core/paginator.py", line 96, in count
    return c()
  File "/Users/hemali/lib/python3.9/site-packages/django/db/models/query.py", line 621, in count
    return self.query.get_count(using=self.db)
  File "/Users/hemali/lib/python3.9/site-packages/django/db/models/sql/query.py", line 559, in get_count
    return obj.get_aggregation(using, ["__count"])["__count"]
  File "/Users/hemali/lib/python3.9/site-packages/django/db/models/sql/query.py", line 544, in get_aggregation
    result = compiler.execute_sql(SINGLE)
  File "/Users/hemali/lib/python3.9/site-packages/django/db/models/sql/compiler.py", line 1398, in execute_sql
    cursor.execute(sql, params)
  File "/Users/hemali/lib/python3.9/site-packages/django/db/backends/utils.py", line 102, in execute
    return super().execute(sql, params)
  File "/Users/hemali/lib/python3.9/site-packages/django/db/backends/utils.py", line 67, in execute
    return self._execute_with_wrappers(
  File "/Users/hemali/lib/python3.9/site-packages/django/db/backends/utils.py", line 80, in _execute_with_wrappers
    return executor(sql, params, many, context)
  File "/Users/hemali/lib/python3.9/site-packages/django/db/backends/utils.py", line 89, in _execute
    return self.cursor.execute(sql, params)
  File "/Users/hemali/lib/python3.9/site-packages/django/db/utils.py", line 91, in __exit__
    raise dj_exc_value.with_traceback(traceback) from exc_value
  File "/Users/hemali/lib/python3.9/site-packages/django/db/backends/utils.py", line 89, in _execute
    return self.cursor.execute(sql, params)
django.db.utils.ProgrammingError: relation "User" does not exist
LINE 1: SELECT COUNT(*) AS "__count" FROM "User"
                                          ^

"GET /admin/app/user/ HTTP/1.1" 500 164205
Internal Server Error: /admin/app/author_books/
Traceback (most recent call last):
  File "/Users/hemali/lib/python3.9/site-packages/django/db/backends/utils.py", line 89, in _execute
    return self.cursor.execute(sql, params)
psycopg2.errors.UndefinedTable: relation "Author_Books" does not exist
LINE 1: SELECT COUNT(*) AS "__count" FROM "Author_Books"
                                          ^


The above exception was the direct cause of the following exception:

Traceback (most recent call last):
  File "/Users/hemali/lib/python3.9/site-packages/django/core/handlers/exception.py", line 56, in inner
    response = get_response(request)
  File "/Users/hemali/lib/python3.9/site-packages/django/core/handlers/base.py", line 197, in _get_response
    response = wrapped_callback(request, *callback_args, **callback_kwargs)
  File "/Users/hemali/lib/python3.9/site-packages/django/contrib/admin/options.py", line 686, in wrapper
    return self.admin_site.admin_view(view)(*args, **kwargs)
  File "/Users/hemali/lib/python3.9/site-packages/django/utils/decorators.py", line 134, in _wrapped_view
    response = view_func(request, *args, **kwargs)
  File "/Users/hemali/lib/python3.9/site-packages/django/views/decorators/cache.py", line 62, in _wrapped_view_func
    response = view_func(request, *args, **kwargs)
  File "/Users/hemali/lib/python3.9/site-packages/django/contrib/admin/sites.py", line 242, in inner
    return view(request, *args, **kwargs)
  File "/Users/hemali/lib/python3.9/site-packages/django/utils/decorators.py", line 46, in _wrapper
    return bound_method(*args, **kwargs)
  File "/Users/hemali/lib/python3.9/site-packages/django/utils/decorators.py", line 134, in _wrapped_view
    response = view_func(request, *args, **kwargs)
  File "/Users/hemali/lib/python3.9/site-packages/django/contrib/admin/options.py", line 1932, in changelist_view
    cl = self.get_changelist_instance(request)
  File "/Users/hemali/lib/python3.9/site-packages/django/contrib/admin/options.py", line 834, in get_changelist_instance
    return ChangeList(
  File "/Users/hemali/lib/python3.9/site-packages/django/contrib/admin/views/main.py", line 123, in __init__
    self.get_results(request)
  File "/Users/hemali/lib/python3.9/site-packages/django/contrib/admin/views/main.py", line 279, in get_results
    result_count = paginator.count
  File "/Users/hemali/lib/python3.9/site-packages/django/utils/functional.py", line 57, in __get__
    res = instance.__dict__[self.name] = self.func(instance)
  File "/Users/hemali/lib/python3.9/site-packages/django/core/paginator.py", line 96, in count
    return c()
  File "/Users/hemali/lib/python3.9/site-packages/django/db/models/query.py", line 621, in count
    return self.query.get_count(using=self.db)
  File "/Users/hemali/lib/python3.9/site-packages/django/db/models/sql/query.py", line 559, in get_count
    return obj.get_aggregation(using, ["__count"])["__count"]
  File "/Users/hemali/lib/python3.9/site-packages/django/db/models/sql/query.py", line 544, in get_aggregation
    result = compiler.execute_sql(SINGLE)
  File "/Users/hemali/lib/python3.9/site-packages/django/db/models/sql/compiler.py", line 1398, in execute_sql
    cursor.execute(sql, params)
  File "/Users/hemali/lib/python3.9/site-packages/django/db/backends/utils.py", line 102, in execute
    return super().execute(sql, params)
  File "/Users/hemali/lib/python3.9/site-packages/django/db/backends/utils.py", line 67, in execute
    return self._execute_with_wrappers(
  File "/Users/hemali/lib/python3.9/site-packages/django/db/backends/utils.py", line 80, in _execute_with_wrappers
    return executor(sql, params, many, context)
  File "/Users/hemali/lib/python3.9/site-packages/django/db/backends/utils.py", line 89, in _execute
    return self.cursor.execute(sql, params)
  File "/Users/hemali/lib/python3.9/site-packages/django/db/utils.py", line 91, in __exit__
    raise dj_exc_value.with_traceback(traceback) from exc_value
  File "/Users/hemali/lib/python3.9/site-packages/django/db/backends/utils.py", line 89, in _execute
    return self.cursor.execute(sql, params)
django.db.utils.ProgrammingError: relation "Author_Books" does not exist
LINE 1: SELECT COUNT(*) AS "__count" FROM "Author_Books"
                                          ^

"GET /admin/app/author_books/ HTTP/1.1" 500 164669
Internal Server Error: /admin/app/category/
Traceback (most recent call last):
  File "/Users/hemali/lib/python3.9/site-packages/django/db/backends/utils.py", line 89, in _execute
    return self.cursor.execute(sql, params)
psycopg2.errors.UndefinedTable: relation "Category" does not exist
LINE 1: SELECT COUNT(*) AS "__count" FROM "Category"
                                          ^


The above exception was the direct cause of the following exception:

Traceback (most recent call last):
  File "/Users/hemali/lib/python3.9/site-packages/django/core/handlers/exception.py", line 56, in inner
    response = get_response(request)
  File "/Users/hemali/lib/python3.9/site-packages/django/core/handlers/base.py", line 197, in _get_response
    response = wrapped_callback(request, *callback_args, **callback_kwargs)
  File "/Users/hemali/lib/python3.9/site-packages/django/contrib/admin/options.py", line 686, in wrapper
    return self.admin_site.admin_view(view)(*args, **kwargs)
  File "/Users/hemali/lib/python3.9/site-packages/django/utils/decorators.py", line 134, in _wrapped_view
    response = view_func(request, *args, **kwargs)
  File "/Users/hemali/lib/python3.9/site-packages/django/views/decorators/cache.py", line 62, in _wrapped_view_func
    response = view_func(request, *args, **kwargs)
  File "/Users/hemali/lib/python3.9/site-packages/django/contrib/admin/sites.py", line 242, in inner
    return view(request, *args, **kwargs)
  File "/Users/hemali/lib/python3.9/site-packages/django/utils/decorators.py", line 46, in _wrapper
    return bound_method(*args, **kwargs)
  File "/Users/hemali/lib/python3.9/site-packages/django/utils/decorators.py", line 134, in _wrapped_view
    response = view_func(request, *args, **kwargs)
  File "/Users/hemali/lib/python3.9/site-packages/django/contrib/admin/options.py", line 1932, in changelist_view
    cl = self.get_changelist_instance(request)
  File "/Users/hemali/lib/python3.9/site-packages/django/contrib/admin/options.py", line 834, in get_changelist_instance
    return ChangeList(
  File "/Users/hemali/lib/python3.9/site-packages/django/contrib/admin/views/main.py", line 123, in __init__
    self.get_results(request)
  File "/Users/hemali/lib/python3.9/site-packages/django/contrib/admin/views/main.py", line 279, in get_results
    result_count = paginator.count
  File "/Users/hemali/lib/python3.9/site-packages/django/utils/functional.py", line 57, in __get__
    res = instance.__dict__[self.name] = self.func(instance)
  File "/Users/hemali/lib/python3.9/site-packages/django/core/paginator.py", line 96, in count
    return c()
  File "/Users/hemali/lib/python3.9/site-packages/django/db/models/query.py", line 621, in count
    return self.query.get_count(using=self.db)
  File "/Users/hemali/lib/python3.9/site-packages/django/db/models/sql/query.py", line 559, in get_count
    return obj.get_aggregation(using, ["__count"])["__count"]
  File "/Users/hemali/lib/python3.9/site-packages/django/db/models/sql/query.py", line 544, in get_aggregation
    result = compiler.execute_sql(SINGLE)
  File "/Users/hemali/lib/python3.9/site-packages/django/db/models/sql/compiler.py", line 1398, in execute_sql
    cursor.execute(sql, params)
  File "/Users/hemali/lib/python3.9/site-packages/django/db/backends/utils.py", line 102, in execute
    return super().execute(sql, params)
  File "/Users/hemali/lib/python3.9/site-packages/django/db/backends/utils.py", line 67, in execute
    return self._execute_with_wrappers(
  File "/Users/hemali/lib/python3.9/site-packages/django/db/backends/utils.py", line 80, in _execute_with_wrappers
    return executor(sql, params, many, context)
  File "/Users/hemali/lib/python3.9/site-packages/django/db/backends/utils.py", line 89, in _execute
    return self.cursor.execute(sql, params)
  File "/Users/hemali/lib/python3.9/site-packages/django/db/utils.py", line 91, in __exit__
    raise dj_exc_value.with_traceback(traceback) from exc_value
  File "/Users/hemali/lib/python3.9/site-packages/django/db/backends/utils.py", line 89, in _execute
    return self.cursor.execute(sql, params)
django.db.utils.ProgrammingError: relation "Category" does not exist
LINE 1: SELECT COUNT(*) AS "__count" FROM "Category"
                                          ^

"GET /admin/app/category/ HTTP/1.1" 500 164457
Internal Server Error: /admin/app/user_author/
Traceback (most recent call last):
  File "/Users/hemali/lib/python3.9/site-packages/django/db/backends/utils.py", line 89, in _execute
    return self.cursor.execute(sql, params)
psycopg2.errors.UndefinedTable: relation "User_Author" does not exist
LINE 1: SELECT COUNT(*) AS "__count" FROM "User_Author"
                                          ^


The above exception was the direct cause of the following exception:

Traceback (most recent call last):
  File "/Users/hemali/lib/python3.9/site-packages/django/core/handlers/exception.py", line 56, in inner
    response = get_response(request)
  File "/Users/hemali/lib/python3.9/site-packages/django/core/handlers/base.py", line 197, in _get_response
    response = wrapped_callback(request, *callback_args, **callback_kwargs)
  File "/Users/hemali/lib/python3.9/site-packages/django/contrib/admin/options.py", line 686, in wrapper
    return self.admin_site.admin_view(view)(*args, **kwargs)
  File "/Users/hemali/lib/python3.9/site-packages/django/utils/decorators.py", line 134, in _wrapped_view
    response = view_func(request, *args, **kwargs)
  File "/Users/hemali/lib/python3.9/site-packages/django/views/decorators/cache.py", line 62, in _wrapped_view_func
    response = view_func(request, *args, **kwargs)
  File "/Users/hemali/lib/python3.9/site-packages/django/contrib/admin/sites.py", line 242, in inner
    return view(request, *args, **kwargs)
  File "/Users/hemali/lib/python3.9/site-packages/django/utils/decorators.py", line 46, in _wrapper
    return bound_method(*args, **kwargs)
  File "/Users/hemali/lib/python3.9/site-packages/django/utils/decorators.py", line 134, in _wrapped_view
    response = view_func(request, *args, **kwargs)
  File "/Users/hemali/lib/python3.9/site-packages/django/contrib/admin/options.py", line 1932, in changelist_view
    cl = self.get_changelist_instance(request)
  File "/Users/hemali/lib/python3.9/site-packages/django/contrib/admin/options.py", line 834, in get_changelist_instance
    return ChangeList(
  File "/Users/hemali/lib/python3.9/site-packages/django/contrib/admin/views/main.py", line 123, in __init__
    self.get_results(request)
  File "/Users/hemali/lib/python3.9/site-packages/django/contrib/admin/views/main.py", line 279, in get_results
    result_count = paginator.count
  File "/Users/hemali/lib/python3.9/site-packages/django/utils/functional.py", line 57, in __get__
    res = instance.__dict__[self.name] = self.func(instance)
  File "/Users/hemali/lib/python3.9/site-packages/django/core/paginator.py", line 96, in count
    return c()
  File "/Users/hemali/lib/python3.9/site-packages/django/db/models/query.py", line 621, in count
    return self.query.get_count(using=self.db)
  File "/Users/hemali/lib/python3.9/site-packages/django/db/models/sql/query.py", line 559, in get_count
    return obj.get_aggregation(using, ["__count"])["__count"]
  File "/Users/hemali/lib/python3.9/site-packages/django/db/models/sql/query.py", line 544, in get_aggregation
    result = compiler.execute_sql(SINGLE)
  File "/Users/hemali/lib/python3.9/site-packages/django/db/models/sql/compiler.py", line 1398, in execute_sql
    cursor.execute(sql, params)
  File "/Users/hemali/lib/python3.9/site-packages/django/db/backends/utils.py", line 102, in execute
    return super().execute(sql, params)
  File "/Users/hemali/lib/python3.9/site-packages/django/db/backends/utils.py", line 67, in execute
    return self._execute_with_wrappers(
  File "/Users/hemali/lib/python3.9/site-packages/django/db/backends/utils.py", line 80, in _execute_with_wrappers
    return executor(sql, params, many, context)
  File "/Users/hemali/lib/python3.9/site-packages/django/db/backends/utils.py", line 89, in _execute
    return self.cursor.execute(sql, params)
  File "/Users/hemali/lib/python3.9/site-packages/django/db/utils.py", line 91, in __exit__
    raise dj_exc_value.with_traceback(traceback) from exc_value
  File "/Users/hemali/lib/python3.9/site-packages/django/db/backends/utils.py", line 89, in _execute
    return self.cursor.execute(sql, params)
django.db.utils.ProgrammingError: relation "User_Author" does not exist
LINE 1: SELECT COUNT(*) AS "__count" FROM "User_Author"
                                          ^

"GET /admin/app/user_author/ HTTP/1.1" 500 164601
Internal Server Error: /admin/app/user/
Traceback (most recent call last):
  File "/Users/hemali/lib/python3.9/site-packages/django/db/backends/utils.py", line 89, in _execute
    return self.cursor.execute(sql, params)
psycopg2.errors.UndefinedTable: relation "User" does not exist
LINE 1: SELECT COUNT(*) AS "__count" FROM "User"
                                          ^


The above exception was the direct cause of the following exception:

Traceback (most recent call last):
  File "/Users/hemali/lib/python3.9/site-packages/django/core/handlers/exception.py", line 56, in inner
    response = get_response(request)
  File "/Users/hemali/lib/python3.9/site-packages/django/core/handlers/base.py", line 197, in _get_response
    response = wrapped_callback(request, *callback_args, **callback_kwargs)
  File "/Users/hemali/lib/python3.9/site-packages/django/contrib/admin/options.py", line 686, in wrapper
    return self.admin_site.admin_view(view)(*args, **kwargs)
  File "/Users/hemali/lib/python3.9/site-packages/django/utils/decorators.py", line 134, in _wrapped_view
    response = view_func(request, *args, **kwargs)
  File "/Users/hemali/lib/python3.9/site-packages/django/views/decorators/cache.py", line 62, in _wrapped_view_func
    response = view_func(request, *args, **kwargs)
  File "/Users/hemali/lib/python3.9/site-packages/django/contrib/admin/sites.py", line 242, in inner
    return view(request, *args, **kwargs)
  File "/Users/hemali/lib/python3.9/site-packages/django/utils/decorators.py", line 46, in _wrapper
    return bound_method(*args, **kwargs)
  File "/Users/hemali/lib/python3.9/site-packages/django/utils/decorators.py", line 134, in _wrapped_view
    response = view_func(request, *args, **kwargs)
  File "/Users/hemali/lib/python3.9/site-packages/django/contrib/admin/options.py", line 1932, in changelist_view
    cl = self.get_changelist_instance(request)
  File "/Users/hemali/lib/python3.9/site-packages/django/contrib/admin/options.py", line 834, in get_changelist_instance
    return ChangeList(
  File "/Users/hemali/lib/python3.9/site-packages/django/contrib/admin/views/main.py", line 123, in __init__
    self.get_results(request)
  File "/Users/hemali/lib/python3.9/site-packages/django/contrib/admin/views/main.py", line 279, in get_results
    result_count = paginator.count
  File "/Users/hemali/lib/python3.9/site-packages/django/utils/functional.py", line 57, in __get__
    res = instance.__dict__[self.name] = self.func(instance)
  File "/Users/hemali/lib/python3.9/site-packages/django/core/paginator.py", line 96, in count
    return c()
  File "/Users/hemali/lib/python3.9/site-packages/django/db/models/query.py", line 621, in count
    return self.query.get_count(using=self.db)
  File "/Users/hemali/lib/python3.9/site-packages/django/db/models/sql/query.py", line 559, in get_count
    return obj.get_aggregation(using, ["__count"])["__count"]
  File "/Users/hemali/lib/python3.9/site-packages/django/db/models/sql/query.py", line 544, in get_aggregation
    result = compiler.execute_sql(SINGLE)
  File "/Users/hemali/lib/python3.9/site-packages/django/db/models/sql/compiler.py", line 1398, in execute_sql
    cursor.execute(sql, params)
  File "/Users/hemali/lib/python3.9/site-packages/django/db/backends/utils.py", line 102, in execute
    return super().execute(sql, params)
  File "/Users/hemali/lib/python3.9/site-packages/django/db/backends/utils.py", line 67, in execute
    return self._execute_with_wrappers(
  File "/Users/hemali/lib/python3.9/site-packages/django/db/backends/utils.py", line 80, in _execute_with_wrappers
    return executor(sql, params, many, context)
  File "/Users/hemali/lib/python3.9/site-packages/django/db/backends/utils.py", line 89, in _execute
    return self.cursor.execute(sql, params)
  File "/Users/hemali/lib/python3.9/site-packages/django/db/utils.py", line 91, in __exit__
    raise dj_exc_value.with_traceback(traceback) from exc_value
  File "/Users/hemali/lib/python3.9/site-packages/django/db/backends/utils.py", line 89, in _execute
    return self.cursor.execute(sql, params)
django.db.utils.ProgrammingError: relation "User" does not exist
LINE 1: SELECT COUNT(*) AS "__count" FROM "User"
                                          ^

"GET /admin/app/user/ HTTP/1.1" 500 164205
Internal Server Error: /admin/app/author_books/
Traceback (most recent call last):
  File "/Users/hemali/lib/python3.9/site-packages/django/db/backends/utils.py", line 89, in _execute
    return self.cursor.execute(sql, params)
psycopg2.errors.UndefinedTable: relation "Author_Books" does not exist
LINE 1: SELECT COUNT(*) AS "__count" FROM "Author_Books"
                                          ^


The above exception was the direct cause of the following exception:

Traceback (most recent call last):
  File "/Users/hemali/lib/python3.9/site-packages/django/core/handlers/exception.py", line 56, in inner
    response = get_response(request)
  File "/Users/hemali/lib/python3.9/site-packages/django/core/handlers/base.py", line 197, in _get_response
    response = wrapped_callback(request, *callback_args, **callback_kwargs)
  File "/Users/hemali/lib/python3.9/site-packages/django/contrib/admin/options.py", line 686, in wrapper
    return self.admin_site.admin_view(view)(*args, **kwargs)
  File "/Users/hemali/lib/python3.9/site-packages/django/utils/decorators.py", line 134, in _wrapped_view
    response = view_func(request, *args, **kwargs)
  File "/Users/hemali/lib/python3.9/site-packages/django/views/decorators/cache.py", line 62, in _wrapped_view_func
    response = view_func(request, *args, **kwargs)
  File "/Users/hemali/lib/python3.9/site-packages/django/contrib/admin/sites.py", line 242, in inner
    return view(request, *args, **kwargs)
  File "/Users/hemali/lib/python3.9/site-packages/django/utils/decorators.py", line 46, in _wrapper
    return bound_method(*args, **kwargs)
  File "/Users/hemali/lib/python3.9/site-packages/django/utils/decorators.py", line 134, in _wrapped_view
    response = view_func(request, *args, **kwargs)
  File "/Users/hemali/lib/python3.9/site-packages/django/contrib/admin/options.py", line 1932, in changelist_view
    cl = self.get_changelist_instance(request)
  File "/Users/hemali/lib/python3.9/site-packages/django/contrib/admin/options.py", line 834, in get_changelist_instance
    return ChangeList(
  File "/Users/hemali/lib/python3.9/site-packages/django/contrib/admin/views/main.py", line 123, in __init__
    self.get_results(request)
  File "/Users/hemali/lib/python3.9/site-packages/django/contrib/admin/views/main.py", line 279, in get_results
    result_count = paginator.count
  File "/Users/hemali/lib/python3.9/site-packages/django/utils/functional.py", line 57, in __get__
    res = instance.__dict__[self.name] = self.func(instance)
  File "/Users/hemali/lib/python3.9/site-packages/django/core/paginator.py", line 96, in count
    return c()
  File "/Users/hemali/lib/python3.9/site-packages/django/db/models/query.py", line 621, in count
    return self.query.get_count(using=self.db)
  File "/Users/hemali/lib/python3.9/site-packages/django/db/models/sql/query.py", line 559, in get_count
    return obj.get_aggregation(using, ["__count"])["__count"]
  File "/Users/hemali/lib/python3.9/site-packages/django/db/models/sql/query.py", line 544, in get_aggregation
    result = compiler.execute_sql(SINGLE)
  File "/Users/hemali/lib/python3.9/site-packages/django/db/models/sql/compiler.py", line 1398, in execute_sql
    cursor.execute(sql, params)
  File "/Users/hemali/lib/python3.9/site-packages/django/db/backends/utils.py", line 102, in execute
    return super().execute(sql, params)
  File "/Users/hemali/lib/python3.9/site-packages/django/db/backends/utils.py", line 67, in execute
    return self._execute_with_wrappers(
  File "/Users/hemali/lib/python3.9/site-packages/django/db/backends/utils.py", line 80, in _execute_with_wrappers
    return executor(sql, params, many, context)
  File "/Users/hemali/lib/python3.9/site-packages/django/db/backends/utils.py", line 89, in _execute
    return self.cursor.execute(sql, params)
  File "/Users/hemali/lib/python3.9/site-packages/django/db/utils.py", line 91, in __exit__
    raise dj_exc_value.with_traceback(traceback) from exc_value
  File "/Users/hemali/lib/python3.9/site-packages/django/db/backends/utils.py", line 89, in _execute
    return self.cursor.execute(sql, params)
django.db.utils.ProgrammingError: relation "Author_Books" does not exist
LINE 1: SELECT COUNT(*) AS "__count" FROM "Author_Books"
                                          ^

"GET /admin/app/author_books/ HTTP/1.1" 500 164669
Not Found: /favicon.ico
"GET /favicon.ico HTTP/1.1" 404 3100
Not Found: /favicon.ico
"GET /favicon.ico HTTP/1.1" 404 3100
